Workbook
Name APRIL22: #REF!
Name AUGUST22: #REF!
Name BPKOTTAYAM: #REF!
Name DECEMBER22: #REF!
Name FEBRUARY22: #REF!
Name JANUARY22: #REF!
Name JULY22: #REF!
Name JUNE22: #REF!
Name MARCH22: #REF!
Name MAYY22: #REF!
Name NOVEMBER22: #REF!
Name OCTOBER22: #REF!
Name PMGRKOTTAYAM: #REF!
Name SEPTEMBER22: #REF!

Sheet GT-SERV
A1: SUMMARY | N1: BRIDGEWAY MOTORS - MIS REPORT | O1: SUMMARY | AC1: SUMMARY | AQ1: CALICUT | BD1: =N1 -> BRIDGEWAY MOTORS - MIS REPORT | BE1: CALICUT | BS1: CALICUT | CE1: CALICUT | CG1: THRISSUR | CT1: =BD1 -> BRIDGEWAY MOTORS - MIS REPORT | CU1: THRISSUR | DI1: THRISSUR | DW1: KOTTAYAM | EJ1: =CT1 -> BRIDGEWAY MOTORS - MIS REPORT | EK1: KOTTAYAM | EY1: KOTTAYAM
A2: 45292 | B2: 45323 | C2: 45352 | D2: 45383 | E2: 45413 | F2: 45444 | G2: 45474 | H2: 45505 | I2: 45536 | J2: 45566 | K2: 45597 | L2: 45627 | M2: YTD 2024 | N2: Particulars | O2: 45658 | P2: 45689 | Q2: 45717 | R2: 45748 | S2: 45778 | T2: 45809 | U2: 45839 | V2: 45870 | W2: 45901 | X2: 45931 | Y2: 45962 | Z2: 45992 | AA2: YTD 2025 | AC2: 45658 | AD2: 45689 | AE2: 45717 | AF2: 45748 | AG2: 45778 | AH2: 45809 | AI2: 45839 | AJ2: 45870 | AK2: 45901 | AL2: 45931 | AM2: 45962 | AN2: 45992 | AO2: YTD 2025 | AQ2: 45292 | AR2: 45323 | AS2: 45352 | AT2: 45383 | AU2: 45413 | AV2: 45444 | AW2: 45474 | AX2: 45505 | AY2: 45536 | AZ2: 45566 | BA2: 45597 | BB2: 45627 | BC2: YTD 2024 | BD2: Particulars | BE2: 45658 | BF2: 45689 | BG2: 45717 | BH2: 45748 | BI2: 45778 | BJ2: 45809 | BK2: 45839 | BL2: 45870 | BM2: 45901 | BN2: 45931 | BO2: 45962 | BP2: 45992 | BQ2: YTD 2025 | BS2: 45658 | BT2: 45689 | BU2: 45717 | BV2: 45748 | BW2: 45778 | BX2: 45809 | BY2: 45839 | BZ2: 45870 | CA2: 45901 | CB2: 45931 | CC2: 45962 | CD2: 45992 | CE2: YTD 2025 | CG2: 45292 | CH2: 45323 | CI2: 45352 | CJ2: 45383 | CK2: 45413 | CL2: 45444 | CM2: 45474 | CN2: 45505 | CO2: 45536 | CP2: 45566 | CQ2: 45597 | CR2: 45627 | CS2: YTD 2024 | CT2: Particulars | CU2: 45658 | CV2: 45689 | CW2: 45717 | CX2: 45748 | CY2: 45778 | CZ2: 45809 | DA2: 45839 | DB2: 45870 | DC2: 45901 | DD2: 45931 | DE2: 45962 | DF2: 45992 | DG2: YTD 2025 | DI2: 45658 | DJ2: 45689 | DK2: 45717 | DL2: 45748 | DM2: 45778 | DN2: 45809 | DO2: 45839 | DP2: 45870 | DQ2: 45901 | DR2: 45931 | DS2: 45962 | DT2: 45992 | DU2: YTD 2025 | DW2: 45292 | DX2: 45323 | DY2: 45352 | DZ2: 45383 | EA2: 45413 | EB2: 45444 | EC2: 45474 | ED2: 45505 | EE2: 45536 | EF2: 45566 | EG2: 45597 | EH2: 45627 | EI2: YTD 2024 | EJ2: Particulars | EK2: 45658 | EL2: 45689 | EM2: 45717 | EN2: 45748 | EO2: 45778 | EP2: 45809 | EQ2: 45839 | ER2: 45870 | ES2: 45901 | ET2: 45931 | EU2: 45962 | EV2: 45992 | EW2: YTD 2025 | EY2: 45658 | EZ2: 45689 | FA2: 45717 | FB2: 45748 | FC2: 45778 | FD2: 45809 | FE2: 45839 | FF2: 45870 | FG2: 45901 | FH2: 45931 | FI2: 45962 | FJ2: 45992 | FK2: YTD 2025
A3: Actual | B3: Actual | C3: Actual | D3: Actual | E3: Actual | F3: Actual | G3: Actual | H3: Actual | I3: Actual | J3: Actual | K3: Actual | L3: Actual | M3: Actual | N3: Rs in Lakhs | O3: Actual | P3: Actual | Q3: Actual | R3: Actual | S3: Actual | T3: Actual | U3: Actual | V3: Actual | W3: Actual | X3: Actual | Y3: Actual | Z3: Actual | AA3: Actual | AC3: Budget | AD3: Budget | AE3: Budget | AF3: Budget | AG3: Budget | AH3: Budget | AI3: Budget | AJ3: Budget | AK3: Budget | AL3: Budget | AM3: Budget | AN3: Budget | AO3: Budget | AQ3: Actual | AR3: Actual | AS3: Actual | AT3: Actual | AU3: Actual | AV3: Actual | AW3: Actual | AX3: Actual | AY3: Actual | AZ3: Actual | BA3: Actual | BB3: Actual | BC3: Actual | BD3: =N3 -> Rs in Lakhs | BE3: Actual | BF3: Actual | BG3: Actual | BH3: Actual | BI3: Actual | BJ3: Actual | BK3: Actual | BL3: Actual | BM3: Actual | BN3: Actual | BO3: Actual | BP3: Actual | BQ3: Actual | BS3: Budget | BT3: Budget | BU3: Budget | BV3: Budget | BW3: Budget | BX3: Budget | BY3: Budget | BZ3: Budget | CA3: Budget | CB3: Budget | CC3: Budget | CD3: Budget | CE3: Budget | CG3: Actual | CH3: Actual | CI3: Actual | CJ3: Actual | CK3: Actual | CL3: Actual | CM3: Actual | CN3: Actual | CO3: Actual | CP3: Actual | CQ3: Actual | CR3: Actual | CS3: Actual | CT3: =BD3 -> Rs in Lakhs | CU3: Actual | CV3: Actual | CW3: Actual | CX3: Actual | CY3: Actual | CZ3: Actual | DA3: Actual | DB3: Actual | DC3: Actual | DD3: Actual | DE3: Actual | DF3: Actual | DG3: Actual | DI3: Budget | DJ3: Budget | DK3: Budget | DL3: Budget | DM3: Budget | DN3: Budget | DO3: Budget | DP3: Budget | DQ3: Budget | DR3: Budget | DS3: Budget | DT3: Budget | DU3: Budget | DW3: Actual | DX3: Actual | DY3: Actual | DZ3: Actual | EA3: Actual | EB3: Actual | EC3: Actual | ED3: Actual | EE3: Actual | EF3: Actual | EG3: Actual | EH3: Actual | EI3: Actual | EJ3: =CT3 -> Rs in Lakhs | EK3: Actual | EL3: Actual | EM3: Actual | EN3: Actual | EO3: Actual | EP3: Actual | EQ3: Actual | ER3: Actual | ES3: Actual | ET3: Actual | EU3: Actual | EV3: Actual | EW3: Actual | EY3: Budget | EZ3: Budget | FA3: Budget | FB3: Budget | FC3: Budget | FD3: Budget | FE3: Budget | FF3: Budget | FG3: Budget | FH3: Budget | FI3: Budget | FJ3: Budget | FK3: Budget
A4: =+AQ4+CG4+DW4 -> 0 | B4: =+AR4+CH4+DX4 -> 0 | C4: =+AS4+CI4+DY4 -> 0 | D4: =+AT4+CJ4+DZ4 -> 0 | E4: =+AU4+CK4+EA4 -> 0 | F4: =+AV4+CL4+EB4 -> 0 | G4: =+AW4+CM4+EC4 -> 0 | H4: =+AX4+CN4+ED4 -> 0 | ... L4: =+BB4+CR4+EH4 -> 0 | M4: =+SUM(A4:L4) -> 0 | N4: No of Cars | O4: =+BE4+CU4+EK4 -> 0 | P4: =+BF4+CV4+EL4 -> 0 | Q4: =+BG4+CW4+EM4 -> 0 | R4: =+BH4+CX4+EN4 -> 0 | S4: =+BI4+CY4+EO4 -> 0 | T4: =+BJ4+CZ4+EP4 -> 0 | U4: =+BK4+DA4+EQ4 -> 0 | V4: =+BL4+DB4+ER4 -> 0 | ... Z4: =+BP4+DF4+EV4 -> 0 | AA4: =+SUM(O4:Z4) -> 0 | AC4: =+BS4+DI4+EY4 -> 0 | AD4: =+BT4+DJ4+EZ4 -> 0 | AE4: =+BU4+DK4+FA4 -> 0 | AF4: =+BV4+DL4+FB4 -> 0 | AG4: =+BW4+DM4+FC4 -> 0 | AH4: =+BX4+DN4+FD4 -> 0 | AI4: =+BY4+DO4+FE4 -> 0 | AJ4: =+BZ4+DP4+FF4 -> 0 | ... AN4: =+CD4+DT4+FJ4 -> 0 | AO4: =+SUM(AC4:AN4) -> 0 | AQ4: =+PMGR!AQ4+BP!AQ4 -> 0 | AR4: =+PMGR!AR4+BP!AR4 -> 0 | AS4: =+PMGR!AS4+BP!AS4 -> 0 | AT4: =+PMGR!AT4+BP!AT4 -> 0 | AU4: =+PMGR!AU4+BP!AU4 -> 0 | AV4: =+PMGR!AV4+BP!AV4 -> 0 | AW4: =+PMGR!AW4+BP!AW4 -> 0 | AX4: =+PMGR!AX4+BP!AX4 -> 0 | ... BB4: =+PMGR!BB4+BP!BB4 -> 0 | BC4: =+SUM(AQ4:BB4) -> 0 | BD4: =N4 -> No of Cars | BE4: =+PMGR!BE4+BP!BE4 -> 0 | BF4: =+PMGR!BF4+BP!BF4 -> 0 | BG4: =+PMGR!BG4+BP!BG4 -> 0 | BH4: =+PMGR!BH4+BP!BH4 -> 0 | BI4: =+PMGR!BI4+BP!BI4 -> 0 | BJ4: =+PMGR!BJ4+BP!BJ4 -> 0 | BK4: =+PMGR!BK4+BP!BK4 -> 0 | BL4: =+PMGR!BL4+BP!BL4 -> 0 | ... BP4: =+PMGR!BP4+BP!BP4 -> 0 | BQ4: =+SUM(BE4:BP4) -> 0 | BS4: =+PMGR!BS4+BP!BS4 -> 0 | BT4: =+PMGR!BT4+BP!BT4 -> 0 | BU4: =+PMGR!BU4+BP!BU4 -> 0 | BV4: =+PMGR!BV4+BP!BV4 -> 0 | BW4: =+PMGR!BW4+BP!BW4 -> 0 | BX4: =+PMGR!BX4+BP!BX4 -> 0 | BY4: =+PMGR!BY4+BP!BY4 -> 0 | BZ4: =+PMGR!BZ4+BP!BZ4 -> 0 | ... CD4: =+PMGR!CD4+BP!CD4 -> 0 | CE4: =+SUM(BS4:CD4) -> 0 | CG4: =+PMGR!CG4+BP!CG4 -> 0 | CH4: =+PMGR!CH4+BP!CH4 -> 0 | CI4: =+PMGR!CI4+BP!CI4 -> 0 | CJ4: =+PMGR!CJ4+BP!CJ4 -> 0 | CK4: =+PMGR!CK4+BP!CK4 -> 0 | CL4: =+PMGR!CL4+BP!CL4 -> 0 | CM4: =+PMGR!CM4+BP!CM4 -> 0 | CN4: =+PMGR!CN4+BP!CN4 -> 0 | ... CR4: =+PMGR!CR4+BP!CR4 -> 0 | CS4: =+SUM(CG4:CR4) -> 0 | CT4: =BD4 -> No of Cars | CU4: =+PMGR!CU4+BP!CU4 -> 0 | CV4: =+PMGR!CV4+BP!CV4 -> 0 | CW4: =+PMGR!CW4+BP!CW4 -> 0 | CX4: =+PMGR!CX4+BP!CX4 -> 0 | CY4: =+PMGR!CY4+BP!CY4 -> 0 | CZ4: =+PMGR!CZ4+BP!CZ4 -> 0 | DA4: =+PMGR!DA4+BP!DA4 -> 0 | DB4: =+PMGR!DB4+BP!DB4 -> 0 | ... DF4: =+PMGR!DF4+BP!DF4 -> 0 | DG4: =+SUM(CU4:DF4) -> 0 | DI4: =+PMGR!DI4+BP!DI4 -> 0 | DJ4: =+PMGR!DJ4+BP!DJ4 -> 0 | DK4: =+PMGR!DK4+BP!DK4 -> 0 | DL4: =+PMGR!DL4+BP!DL4 -> 0 | DM4: =+PMGR!DM4+BP!DM4 -> 0 | DN4: =+PMGR!DN4+BP!DN4 -> 0 | DO4: =+PMGR!DO4+BP!DO4 -> 0 | DP4: =+PMGR!DP4+BP!DP4 -> 0 | ... DT4: =+PMGR!DT4+BP!DT4 -> 0 | DU4: =+SUM(DI4:DT4) -> 0 | DW4: =+PMGR!DW4+BP!DW4 -> 0 | DX4: =+PMGR!DX4+BP!DX4 -> 0 | DY4: =+PMGR!DY4+BP!DY4 -> 0 | DZ4: =+PMGR!DZ4+BP!DZ4 -> 0 | EA4: =+PMGR!EA4+BP!EA4 -> 0 | EB4: =+PMGR!EB4+BP!EB4 -> 0 | EC4: =+PMGR!EC4+BP!EC4 -> 0 | ED4: =+PMGR!ED4+BP!ED4 -> 0 | ... EH4: =+PMGR!EH4+BP!EH4 -> 0 | EI4: =+SUM(DW4:EH4) -> 0 | EJ4: =CT4 -> No of Cars | EK4: =+PMGR!EK4+BP!EK4 -> 0 | EL4: =+PMGR!EL4+BP!EL4 -> 0 | EM4: =+PMGR!EM4+BP!EM4 -> 0 | EN4: =+PMGR!EN4+BP!EN4 -> 0 | EO4: =+PMGR!EO4+BP!EO4 -> 0 | EP4: =+PMGR!EP4+BP!EP4 -> 0 | EQ4: =+PMGR!EQ4+BP!EQ4 -> 0 | ER4: =+PMGR!ER4+BP!ER4 -> 0 | ... EV4: =+PMGR!EV4+BP!EV4 -> 0 | EW4: =+SUM(EK4:EV4) -> 0 | EY4: =+PMGR!EY4+BP!EY4 -> 0 | EZ4: =+PMGR!EZ4+BP!EZ4 -> 0 | FA4: =+PMGR!FA4+BP!FA4 -> 0 | FB4: =+PMGR!FB4+BP!FB4 -> 0 | FC4: =+PMGR!FC4+BP!FC4 -> 0 | FD4: =+PMGR!FD4+BP!FD4 -> 0 | FE4: =+PMGR!FE4+BP!FE4 -> 0 | FF4: =+PMGR!FF4+BP!FF4 -> 0 | ... FJ4: =+PMGR!FJ4+BP!FJ4 -> 0 | FK4: =+SUM(EY4:FJ4) -> 0
N5: New Car Sales | AQ5: =+PMGR!AQ5+BP!AQ5 -> 0 | AR5: =+PMGR!AR5+BP!AR5 -> 0 | AS5: =+PMGR!AS5+BP!AS5 -> 0 | AT5: =+PMGR!AT5+BP!AT5 -> 0 | AU5: =+PMGR!AU5+BP!AU5 -> 0 | AV5: =+PMGR!AV5+BP!AV5 -> 0 | AW5: =+PMGR!AW5+BP!AW5 -> 0 | AX5: =+PMGR!AX5+BP!AX5 -> 0 | ... BB5: =+PMGR!BB5+BP!BB5 -> 0 | BD5: =N5 -> New Car Sales | BE5: =+PMGR!BE5+BP!BE5 -> 0 | BF5: =+PMGR!BF5+BP!BF5 -> 0 | BG5: =+PMGR!BG5+BP!BG5 -> 0 | BH5: =+PMGR!BH5+BP!BH5 -> 0 | BI5: =+PMGR!BI5+BP!BI5 -> 0 | BJ5: =+PMGR!BJ5+BP!BJ5 -> 0 | BK5: =+PMGR!BK5+BP!BK5 -> 0 | BL5: =+PMGR!BL5+BP!BL5 -> 0 | ... BP5: =+PMGR!BP5+BP!BP5 -> 0 | BS5: =+PMGR!BS5+BP!BS5 -> 0 | BT5: =+PMGR!BT5+BP!BT5 -> 0 | BU5: =+PMGR!BU5+BP!BU5 -> 0 | BV5: =+PMGR!BV5+BP!BV5 -> 0 | BW5: =+PMGR!BW5+BP!BW5 -> 0 | BX5: =+PMGR!BX5+BP!BX5 -> 0 | BY5: =+PMGR!BY5+BP!BY5 -> 0 | BZ5: =+PMGR!BZ5+BP!BZ5 -> 0 | ... CD5: =+PMGR!CD5+BP!CD5 -> 0 | CG5: =+PMGR!CG5+BP!CG5 -> 0 | CH5: =+PMGR!CH5+BP!CH5 -> 0 | CI5: =+PMGR!CI5+BP!CI5 -> 0 | CJ5: =+PMGR!CJ5+BP!CJ5 -> 0 | CK5: =+PMGR!CK5+BP!CK5 -> 0 | CL5: =+PMGR!CL5+BP!CL5 -> 0 | CM5: =+PMGR!CM5+BP!CM5 -> 0 | CN5: =+PMGR!CN5+BP!CN5 -> 0 | ... CR5: =+PMGR!CR5+BP!CR5 -> 0 | CT5: =BD5 -> New Car Sales | CU5: =+PMGR!CU5+BP!CU5 -> 0 | CV5: =+PMGR!CV5+BP!CV5 -> 0 | CW5: =+PMGR!CW5+BP!CW5 -> 0 | CX5: =+PMGR!CX5+BP!CX5 -> 0 | CY5: =+PMGR!CY5+BP!CY5 -> 0 | CZ5: =+PMGR!CZ5+BP!CZ5 -> 0 | DA5: =+PMGR!DA5+BP!DA5 -> 0 | DB5: =+PMGR!DB5+BP!DB5 -> 0 | ... DF5: =+PMGR!DF5+BP!DF5 -> 0 | DI5: =+PMGR!DI5+BP!DI5 -> 0 | DJ5: =+PMGR!DJ5+BP!DJ5 -> 0 | DK5: =+PMGR!DK5+BP!DK5 -> 0 | DL5: =+PMGR!DL5+BP!DL5 -> 0 | DM5: =+PMGR!DM5+BP!DM5 -> 0 | DN5: =+PMGR!DN5+BP!DN5 -> 0 | DO5: =+PMGR!DO5+BP!DO5 -> 0 | DP5: =+PMGR!DP5+BP!DP5 -> 0 | ... DT5: =+PMGR!DT5+BP!DT5 -> 0 | DW5: =+PMGR!DW5+BP!DW5 -> 0 | DX5: =+PMGR!DX5+BP!DX5 -> 0 | DY5: =+PMGR!DY5+BP!DY5 -> 0 | DZ5: =+PMGR!DZ5+BP!DZ5 -> 0 | EA5: =+PMGR!EA5+BP!EA5 -> 0 | EB5: =+PMGR!EB5+BP!EB5 -> 0 | EC5: =+PMGR!EC5+BP!EC5 -> 0 | ED5: =+PMGR!ED5+BP!ED5 -> 0 | ... EH5: =+PMGR!EH5+BP!EH5 -> 0 | EJ5: =CT5 -> New Car Sales | EK5: =+PMGR!EK5+BP!EK5 -> 0 | EL5: =+PMGR!EL5+BP!EL5 -> 0 | EM5: =+PMGR!EM5+BP!EM5 -> 0 | EN5: =+PMGR!EN5+BP!EN5 -> 0 | EO5: =+PMGR!EO5+BP!EO5 -> 0 | EP5: =+PMGR!EP5+BP!EP5 -> 0 | EQ5: =+PMGR!EQ5+BP!EQ5 -> 0 | ER5: =+PMGR!ER5+BP!ER5 -> 0 | ... EV5: =+PMGR!EV5+BP!EV5 -> 0 | EY5: =+PMGR!EY5+BP!EY5 -> 0 | EZ5: =+PMGR!EZ5+BP!EZ5 -> 0 | FA5: =+PMGR!FA5+BP!FA5 -> 0 | FB5: =+PMGR!FB5+BP!FB5 -> 0 | FC5: =+PMGR!FC5+BP!FC5 -> 0 | FD5: =+PMGR!FD5+BP!FD5 -> 0 | FE5: =+PMGR!FE5+BP!FE5 -> 0 | FF5: =+PMGR!FF5+BP!FF5 -> 0 | ... FJ5: =+PMGR!FJ5+BP!FJ5 -> 0
A6: =+A7+A8+A13 -> 0 | B6: =+B7+B8+B13 -> 0 | C6: =+C7+C8+C13 -> 0 | D6: =+D7+D8+D13 -> 0 | E6: =+E7+E8+E13 -> 0 | F6: =+F7+F8+F13 -> 0 | G6: =+G7+G8+G13 -> 0 | H6: =+H7+H8+H13 -> 0 | ... L6: =+L7+L8+L13 -> 0 | M6: =+SUM(A6:L6) -> 0 | N6: Total Commission | O6: =+O7+O8+O13 -> 0 | P6: =+P7+P8+P13 -> 0 | Q6: =+Q7+Q8+Q13 -> 0 | R6: =+R7+R8+R13 -> 0 | S6: =+S7+S8+S13 -> 0 | T6: =+T7+T8+T13 -> 0 | U6: =+U7+U8+U13 -> 0 | V6: =+V7+V8+V13 -> 0 | ... Z6: =+Z7+Z8+Z13 -> 0 | AA6: =+SUM(O6:Z6) -> 0 | AC6: =+AC7+AC8+AC13 -> 0 | AD6: =+AD7+AD8+AD13 -> 0 | AE6: =+AE7+AE8+AE13 -> 0 | AF6: =+AF7+AF8+AF13 -> 0 | AG6: =+AG7+AG8+AG13 -> 0 | AH6: =+AH7+AH8+AH13 -> 0 | AI6: =+AI7+AI8+AI13 -> 0 | AJ6: =+AJ7+AJ8+AJ13 -> 0 | ... AN6: =+AN7+AN8+AN13 -> 0 | AO6: =+SUM(AC6:AN6) -> 0 | AQ6: =+AQ7+AQ8+AQ13 -> 0 | AR6: =+AR7+AR8+AR13 -> 0 | AS6: =+AS7+AS8+AS13 -> 0 | AT6: =+AT7+AT8+AT13 -> 0 | AU6: =+AU7+AU8+AU13 -> 0 | AV6: =+AV7+AV8+AV13 -> 0 | AW6: =+AW7+AW8+AW13 -> 0 | AX6: =+AX7+AX8+AX13 -> 0 | ... BB6: =+BB7+BB8+BB13 -> 0 | BC6: =+SUM(AQ6:BB6) -> 0 | BD6: =N6 -> Total Commission | BE6: =+BE7+BE8+BE13 -> 0 | BF6: =+BF7+BF8+BF13 -> 0 | BG6: =+BG7+BG8+BG13 -> 0 | BH6: =+BH7+BH8+BH13 -> 0 | BI6: =+BI7+BI8+BI13 -> 0 | BJ6: =+BJ7+BJ8+BJ13 -> 0 | BK6: =+BK7+BK8+BK13 -> 0 | BL6: =+BL7+BL8+BL13 -> 0 | ... BP6: =+BP7+BP8+BP13 -> 0 | BQ6: =+SUM(BE6:BP6) -> 0 | BS6: =+BS7+BS8+BS13 -> 0 | BT6: =+BT7+BT8+BT13 -> 0 | BU6: =+BU7+BU8+BU13 -> 0 | BV6: =+BV7+BV8+BV13 -> 0 | BW6: =+BW7+BW8+BW13 -> 0 | BX6: =+BX7+BX8+BX13 -> 0 | BY6: =+BY7+BY8+BY13 -> 0 | BZ6: =+BZ7+BZ8+BZ13 -> 0 | ... CD6: =+CD7+CD8+CD13 -> 0 | CE6: =+SUM(BS6:CD6) -> 0 | CG6: =+CG7+CG8+CG13 -> 0 | CH6: =+CH7+CH8+CH13 -> 0 | CI6: =+CI7+CI8+CI13 -> 0 | CJ6: =+CJ7+CJ8+CJ13 -> 0 | CK6: =+CK7+CK8+CK13 -> 0 | CL6: =+CL7+CL8+CL13 -> 0 | CM6: =+CM7+CM8+CM13 -> 0 | CN6: =+CN7+CN8+CN13 -> 0 | ... CR6: =+CR7+CR8+CR13 -> 0 | CS6: =+SUM(CG6:CR6) -> 0 | CT6: =BD6 -> Total Commission | CU6: =+CU7+CU8+CU13 -> 0 | CV6: =+CV7+CV8+CV13 -> 0 | CW6: =+CW7+CW8+CW13 -> 0 | CX6: =+CX7+CX8+CX13 -> 0 | CY6: =+CY7+CY8+CY13 -> 0 | CZ6: =+CZ7+CZ8+CZ13 -> 0 | DA6: =+DA7+DA8+DA13 -> 0 | DB6: =+DB7+DB8+DB13 -> 0 | ... DF6: =+DF7+DF8+DF13 -> 0 | DG6: =+SUM(CU6:DF6) -> 0 | DI6: =+DI7+DI8+DI13 -> 0 | DJ6: =+DJ7+DJ8+DJ13 -> 0 | DK6: =+DK7+DK8+DK13 -> 0 | DL6: =+DL7+DL8+DL13 -> 0 | DM6: =+DM7+DM8+DM13 -> 0 | DN6: =+DN7+DN8+DN13 -> 0 | DO6: =+DO7+DO8+DO13 -> 0 | DP6: =+DP7+DP8+DP13 -> 0 | ... DT6: =+DT7+DT8+DT13 -> 0 | DU6: =+SUM(DI6:DT6) -> 0 | DW6: =+DW7+DW8+DW13 -> 0 | DX6: =+DX7+DX8+DX13 -> 0 | DY6: =+DY7+DY8+DY13 -> 0 | DZ6: =+DZ7+DZ8+DZ13 -> 0 | EA6: =+EA7+EA8+EA13 -> 0 | EB6: =+EB7+EB8+EB13 -> 0 | EC6: =+EC7+EC8+EC13 -> 0 | ED6: =+ED7+ED8+ED13 -> 0 | ... EH6: =+EH7+EH8+EH13 -> 0 | EI6: =+SUM(DW6:EH6) -> 0 | EJ6: =CT6 -> Total Commission | EK6: =+EK7+EK8+EK13 -> 0 | EL6: =+EL7+EL8+EL13 -> 0 | EM6: =+EM7+EM8+EM13 -> 0 | EN6: =+EN7+EN8+EN13 -> 0 | EO6: =+EO7+EO8+EO13 -> 0 | EP6: =+EP7+EP8+EP13 -> 0 | EQ6: =+EQ7+EQ8+EQ13 -> 0 | ER6: =+ER7+ER8+ER13 -> 0 | ... EV6: =+EV7+EV8+EV13 -> 0 | EW6: =+SUM(EK6:EV6) -> 0 | EY6: =+EY7+EY8+EY13 -> 0 | EZ6: =+EZ7+EZ8+EZ13 -> 0 | FA6: =+FA7+FA8+FA13 -> 0 | FB6: =+FB7+FB8+FB13 -> 0 | FC6: =+FC7+FC8+FC13 -> 0 | FD6: =+FD7+FD8+FD13 -> 0 | FE6: =+FE7+FE8+FE13 -> 0 | FF6: =+FF7+FF8+FF13 -> 0 | ... FJ6: =+FJ7+FJ8+FJ13 -> 0 | FK6: =+SUM(EY6:FJ6) -> 0
A7: =+AQ7+CG7+DW7 -> 0 | B7: =+AR7+CH7+DX7 -> 0 | C7: =+AS7+CI7+DY7 -> 0 | D7: =+AT7+CJ7+DZ7 -> 0 | E7: =+AU7+CK7+EA7 -> 0 | F7: =+AV7+CL7+EB7 -> 0 | G7: =+AW7+CM7+EC7 -> 0 | H7: =+AX7+CN7+ED7 -> 0 | ... L7: =+BB7+CR7+EH7 -> 0 | M7: =+SUM(A7:L7) -> 0 | N7: Fixed Commission | O7: =+BE7+CU7+EK7 -> 0 | P7: =+BF7+CV7+EL7 -> 0 | Q7: =+BG7+CW7+EM7 -> 0 | R7: =+BH7+CX7+EN7 -> 0 | S7: =+BI7+CY7+EO7 -> 0 | T7: =+BJ7+CZ7+EP7 -> 0 | U7: =+BK7+DA7+EQ7 -> 0 | V7: =+BL7+DB7+ER7 -> 0 | ... Z7: =+BP7+DF7+EV7 -> 0 | AA7: =+SUM(O7:Z7) -> 0 | AC7: =+BS7+DI7+EY7 -> 0 | AD7: =+BT7+DJ7+EZ7 -> 0 | AE7: =+BU7+DK7+FA7 -> 0 | AF7: =+BV7+DL7+FB7 -> 0 | AG7: =+BW7+DM7+FC7 -> 0 | AH7: =+BX7+DN7+FD7 -> 0 | AI7: =+BY7+DO7+FE7 -> 0 | AJ7: =+BZ7+DP7+FF7 -> 0 | ... AN7: =+CD7+DT7+FJ7 -> 0 | AO7: =+SUM(AC7:AN7) -> 0 | AQ7: =+PMGR!AQ7+BP!AQ7 -> 0 | AR7: =+PMGR!AR7+BP!AR7 -> 0 | AS7: =+PMGR!AS7+BP!AS7 -> 0 | AT7: =+PMGR!AT7+BP!AT7 -> 0 | AU7: =+PMGR!AU7+BP!AU7 -> 0 | AV7: =+PMGR!AV7+BP!AV7 -> 0 | AW7: =+PMGR!AW7+BP!AW7 -> 0 | AX7: =+PMGR!AX7+BP!AX7 -> 0 | ... BB7: =+PMGR!BB7+BP!BB7 -> 0 | BC7: =+SUM(AQ7:BB7) -> 0 | BD7: =N7 -> Fixed Commission | BE7: =+PMGR!BE7+BP!BE7 -> 0 | BF7: =+PMGR!BF7+BP!BF7 -> 0 | BG7: =+PMGR!BG7+BP!BG7 -> 0 | BH7: =+PMGR!BH7+BP!BH7 -> 0 | BI7: =+PMGR!BI7+BP!BI7 -> 0 | BJ7: =+PMGR!BJ7+BP!BJ7 -> 0 | BK7: =+PMGR!BK7+BP!BK7 -> 0 | BL7: =+PMGR!BL7+BP!BL7 -> 0 | ... BP7: =+PMGR!BP7+BP!BP7 -> 0 | BQ7: =+SUM(BE7:BP7) -> 0 | BS7: =+PMGR!BS7+BP!BS7 -> 0 | BT7: =+PMGR!BT7+BP!BT7 -> 0 | BU7: =+PMGR!BU7+BP!BU7 -> 0 | BV7: =+PMGR!BV7+BP!BV7 -> 0 | BW7: =+PMGR!BW7+BP!BW7 -> 0 | BX7: =+PMGR!BX7+BP!BX7 -> 0 | BY7: =+PMGR!BY7+BP!BY7 -> 0 | BZ7: =+PMGR!BZ7+BP!BZ7 -> 0 | ... CD7: =+PMGR!CD7+BP!CD7 -> 0 | CE7: =+SUM(BS7:CD7) -> 0 | CG7: =+PMGR!CG7+BP!CG7 -> 0 | CH7: =+PMGR!CH7+BP!CH7 -> 0 | CI7: =+PMGR!CI7+BP!CI7 -> 0 | CJ7: =+PMGR!CJ7+BP!CJ7 -> 0 | CK7: =+PMGR!CK7+BP!CK7 -> 0 | CL7: =+PMGR!CL7+BP!CL7 -> 0 | CM7: =+PMGR!CM7+BP!CM7 -> 0 | CN7: =+PMGR!CN7+BP!CN7 -> 0 | ... CR7: =+PMGR!CR7+BP!CR7 -> 0 | CS7: =+SUM(CG7:CR7) -> 0 | CT7: =BD7 -> Fixed Commission | CU7: =+PMGR!CU7+BP!CU7 -> 0 | CV7: =+PMGR!CV7+BP!CV7 -> 0 | CW7: =+PMGR!CW7+BP!CW7 -> 0 | CX7: =+PMGR!CX7+BP!CX7 -> 0 | CY7: =+PMGR!CY7+BP!CY7 -> 0 | CZ7: =+PMGR!CZ7+BP!CZ7 -> 0 | DA7: =+PMGR!DA7+BP!DA7 -> 0 | DB7: =+PMGR!DB7+BP!DB7 -> 0 | ... DF7: =+PMGR!DF7+BP!DF7 -> 0 | DG7: =+SUM(CU7:DF7) -> 0 | DI7: =+PMGR!DI7+BP!DI7 -> 0 | DJ7: =+PMGR!DJ7+BP!DJ7 -> 0 | DK7: =+PMGR!DK7+BP!DK7 -> 0 | DL7: =+PMGR!DL7+BP!DL7 -> 0 | DM7: =+PMGR!DM7+BP!DM7 -> 0 | DN7: =+PMGR!DN7+BP!DN7 -> 0 | DO7: =+PMGR!DO7+BP!DO7 -> 0 | DP7: =+PMGR!DP7+BP!DP7 -> 0 | ... DT7: =+PMGR!DT7+BP!DT7 -> 0 | DU7: =+SUM(DI7:DT7) -> 0 | DW7: =+PMGR!DW7+BP!DW7 -> 0 | DX7: =+PMGR!DX7+BP!DX7 -> 0 | DY7: =+PMGR!DY7+BP!DY7 -> 0 | DZ7: =+PMGR!DZ7+BP!DZ7 -> 0 | EA7: =+PMGR!EA7+BP!EA7 -> 0 | EB7: =+PMGR!EB7+BP!EB7 -> 0 | EC7: =+PMGR!EC7+BP!EC7 -> 0 | ED7: =+PMGR!ED7+BP!ED7 -> 0 | ... EH7: =+PMGR!EH7+BP!EH7 -> 0 | EI7: =+SUM(DW7:EH7) -> 0 | EJ7: =CT7 -> Fixed Commission | EK7: =+PMGR!EK7+BP!EK7 -> 0 | EL7: =+PMGR!EL7+BP!EL7 -> 0 | EM7: =+PMGR!EM7+BP!EM7 -> 0 | EN7: =+PMGR!EN7+BP!EN7 -> 0 | EO7: =+PMGR!EO7+BP!EO7 -> 0 | EP7: =+PMGR!EP7+BP!EP7 -> 0 | EQ7: =+PMGR!EQ7+BP!EQ7 -> 0 | ER7: =+PMGR!ER7+BP!ER7 -> 0 | ... EV7: =+PMGR!EV7+BP!EV7 -> 0 | EW7: =+SUM(EK7:EV7) -> 0 | EY7: =+PMGR!EY7+BP!EY7 -> 0 | EZ7: =+PMGR!EZ7+BP!EZ7 -> 0 | FA7: =+PMGR!FA7+BP!FA7 -> 0 | FB7: =+PMGR!FB7+BP!FB7 -> 0 | FC7: =+PMGR!FC7+BP!FC7 -> 0 | FD7: =+PMGR!FD7+BP!FD7 -> 0 | FE7: =+PMGR!FE7+BP!FE7 -> 0 | FF7: =+PMGR!FF7+BP!FF7 -> 0 | ... FJ7: =+PMGR!FJ7+BP!FJ7 -> 0 | FK7: =+SUM(EY7:FJ7) -> 0
A8: =+SUM(A9:A12) -> 0 | B8: =+SUM(B9:B12) -> 0 | C8: =+SUM(C9:C12) -> 0 | D8: =+SUM(D9:D12) -> 0 | E8: =+SUM(E9:E12) -> 0 | F8: =+SUM(F9:F12) -> 0 | G8: =+SUM(G9:G12) -> 0 | H8: =+SUM(H9:H12) -> 0 | ... L8: =+SUM(L9:L12) -> 0 | M8: =+SUM(A8:L8) -> 0 | N8: Target achievement bonus | O8: =+SUM(O9:O12) -> 0 | P8: =+SUM(P9:P12) -> 0 | Q8: =+SUM(Q9:Q12) -> 0 | R8: =+SUM(R9:R12) -> 0 | S8: =+SUM(S9:S12) -> 0 | T8: =+SUM(T9:T12) -> 0 | U8: =+SUM(U9:U12) -> 0 | V8: =+SUM(V9:V12) -> 0 | ... Z8: =+SUM(Z9:Z12) -> 0 | AA8: =+SUM(O8:Z8) -> 0 | AC8: =+SUM(AC9:AC12) -> 0 | AD8: =+SUM(AD9:AD12) -> 0 | AE8: =+SUM(AE9:AE12) -> 0 | AF8: =+SUM(AF9:AF12) -> 0 | AG8: =+SUM(AG9:AG12) -> 0 | AH8: =+SUM(AH9:AH12) -> 0 | AI8: =+SUM(AI9:AI12) -> 0 | AJ8: =+SUM(AJ9:AJ12) -> 0 | ... AN8: =+SUM(AN9:AN12) -> 0 | AO8: =+SUM(AC8:AN8) -> 0 | AQ8: =+SUM(AQ9:AQ12) -> 0 | AR8: =+SUM(AR9:AR12) -> 0 | AS8: =+SUM(AS9:AS12) -> 0 | AT8: =+SUM(AT9:AT12) -> 0 | AU8: =+SUM(AU9:AU12) -> 0 | AV8: =+SUM(AV9:AV12) -> 0 | AW8: =+SUM(AW9:AW12) -> 0 | AX8: =+SUM(AX9:AX12) -> 0 | ... BB8: =+SUM(BB9:BB12) -> 0 | BC8: =+SUM(AQ8:BB8) -> 0 | BD8: =N8 -> Target achievement bonus | BE8: =+SUM(BE9:BE12) -> 0 | BF8: =+SUM(BF9:BF12) -> 0 | BG8: =+SUM(BG9:BG12) -> 0 | BH8: =+SUM(BH9:BH12) -> 0 | BI8: =+SUM(BI9:BI12) -> 0 | BJ8: =+SUM(BJ9:BJ12) -> 0 | BK8: =+SUM(BK9:BK12) -> 0 | BL8: =+SUM(BL9:BL12) -> 0 | ... BP8: =+SUM(BP9:BP12) -> 0 | BQ8: =+SUM(BE8:BP8) -> 0 | BS8: =+SUM(BS9:BS12) -> 0 | BT8: =+SUM(BT9:BT12) -> 0 | BU8: =+SUM(BU9:BU12) -> 0 | BV8: =+SUM(BV9:BV12) -> 0 | BW8: =+SUM(BW9:BW12) -> 0 | BX8: =+SUM(BX9:BX12) -> 0 | BY8: =+SUM(BY9:BY12) -> 0 | BZ8: =+SUM(BZ9:BZ12) -> 0 | ... CD8: =+SUM(CD9:CD12) -> 0 | CE8: =+SUM(BS8:CD8) -> 0 | CG8: =+SUM(CG9:CG12) -> 0 | CH8: =+SUM(CH9:CH12) -> 0 | CI8: =+SUM(CI9:CI12) -> 0 | CJ8: =+SUM(CJ9:CJ12) -> 0 | CK8: =+SUM(CK9:CK12) -> 0 | CL8: =+SUM(CL9:CL12) -> 0 | CM8: =+SUM(CM9:CM12) -> 0 | CN8: =+SUM(CN9:CN12) -> 0 | ... CR8: =+SUM(CR9:CR12) -> 0 | CS8: =+SUM(CG8:CR8) -> 0 | CT8: =BD8 -> Target achievement bonus | CU8: =+SUM(CU9:CU12) -> 0 | CV8: =+SUM(CV9:CV12) -> 0 | CW8: =+SUM(CW9:CW12) -> 0 | CX8: =+SUM(CX9:CX12) -> 0 | CY8: =+SUM(CY9:CY12) -> 0 | CZ8: =+SUM(CZ9:CZ12) -> 0 | DA8: =+SUM(DA9:DA12) -> 0 | DB8: =+SUM(DB9:DB12) -> 0 | ... DF8: =+SUM(DF9:DF12) -> 0 | DG8: =+SUM(CU8:DF8) -> 0 | DI8: =+SUM(DI9:DI12) -> 0 | DJ8: =+SUM(DJ9:DJ12) -> 0 | DK8: =+SUM(DK9:DK12) -> 0 | DL8: =+SUM(DL9:DL12) -> 0 | DM8: =+SUM(DM9:DM12) -> 0 | DN8: =+SUM(DN9:DN12) -> 0 | DO8: =+SUM(DO9:DO12) -> 0 | DP8: =+SUM(DP9:DP12) -> 0 | ... DT8: =+SUM(DT9:DT12) -> 0 | DU8: =+SUM(DI8:DT8) -> 0 | DW8: =+SUM(DW9:DW12) -> 0 | DX8: =+SUM(DX9:DX12) -> 0 | DY8: =+SUM(DY9:DY12) -> 0 | DZ8: =+SUM(DZ9:DZ12) -> 0 | EA8: =+SUM(EA9:EA12) -> 0 | EB8: =+SUM(EB9:EB12) -> 0 | EC8: =+SUM(EC9:EC12) -> 0 | ED8: =+SUM(ED9:ED12) -> 0 | ... EH8: =+SUM(EH9:EH12) -> 0 | EI8: =+SUM(DW8:EH8) -> 0 | EJ8: =CT8 -> Target achievement bonus | EK8: =+SUM(EK9:EK12) -> 0 | EL8: =+SUM(EL9:EL12) -> 0 | EM8: =+SUM(EM9:EM12) -> 0 | EN8: =+SUM(EN9:EN12) -> 0 | EO8: =+SUM(EO9:EO12) -> 0 | EP8: =+SUM(EP9:EP12) -> 0 | EQ8: =+SUM(EQ9:EQ12) -> 0 | ER8: =+SUM(ER9:ER12) -> 0 | ... EV8: =+SUM(EV9:EV12) -> 0 | EW8: =+SUM(EK8:EV8) -> 0 | EY8: =+SUM(EY9:EY12) -> 0 | EZ8: =+SUM(EZ9:EZ12) -> 0 | FA8: =+SUM(FA9:FA12) -> 0 | FB8: =+SUM(FB9:FB12) -> 0 | FC8: =+SUM(FC9:FC12) -> 0 | FD8: =+SUM(FD9:FD12) -> 0 | FE8: =+SUM(FE9:FE12) -> 0 | FF8: =+SUM(FF9:FF12) -> 0 | ... FJ8: =+SUM(FJ9:FJ12) -> 0 | FK8: =+SUM(EY8:FJ8) -> 0
A9: =+AQ9+CG9+DW9 -> 0 | B9: =+AR9+CH9+DX9 -> 0 | C9: =+AS9+CI9+DY9 -> 0 | D9: =+AT9+CJ9+DZ9 -> 0 | E9: =+AU9+CK9+EA9 -> 0 | F9: =+AV9+CL9+EB9 -> 0 | G9: =+AW9+CM9+EC9 -> 0 | H9: =+AX9+CN9+ED9 -> 0 | ... L9: =+BB9+CR9+EH9 -> 0 | M9: =+SUM(A9:L9) -> 0 | N9: Sales Target Bonus | O9: =+BE9+CU9+EK9 -> 0 | P9: =+BF9+CV9+EL9 -> 0 | Q9: =+BG9+CW9+EM9 -> 0 | R9: =+BH9+CX9+EN9 -> 0 | S9: =+BI9+CY9+EO9 -> 0 | T9: =+BJ9+CZ9+EP9 -> 0 | U9: =+BK9+DA9+EQ9 -> 0 | V9: =+BL9+DB9+ER9 -> 0 | ... Z9: =+BP9+DF9+EV9 -> 0 | AA9: =+SUM(O9:Z9) -> 0 | AC9: =+BS9+DI9+EY9 -> 0 | AD9: =+BT9+DJ9+EZ9 -> 0 | AE9: =+BU9+DK9+FA9 -> 0 | AF9: =+BV9+DL9+FB9 -> 0 | AG9: =+BW9+DM9+FC9 -> 0 | AH9: =+BX9+DN9+FD9 -> 0 | AI9: =+BY9+DO9+FE9 -> 0 | AJ9: =+BZ9+DP9+FF9 -> 0 | ... AN9: =+CD9+DT9+FJ9 -> 0 | AO9: =+SUM(AC9:AN9) -> 0 | AQ9: =+PMGR!AQ9+BP!AQ9 -> 0 | AR9: =+PMGR!AR9+BP!AR9 -> 0 | AS9: =+PMGR!AS9+BP!AS9 -> 0 | AT9: =+PMGR!AT9+BP!AT9 -> 0 | AU9: =+PMGR!AU9+BP!AU9 -> 0 | AV9: =+PMGR!AV9+BP!AV9 -> 0 | AW9: =+PMGR!AW9+BP!AW9 -> 0 | AX9: =+PMGR!AX9+BP!AX9 -> 0 | ... BB9: =+PMGR!BB9+BP!BB9 -> 0 | BC9: =+SUM(AQ9:BB9) -> 0 | BD9: Sales Target Bonus | BE9: =+PMGR!BE9+BP!BE9 -> 0 | BF9: =+PMGR!BF9+BP!BF9 -> 0 | BG9: =+PMGR!BG9+BP!BG9 -> 0 | BH9: =+PMGR!BH9+BP!BH9 -> 0 | BI9: =+PMGR!BI9+BP!BI9 -> 0 | BJ9: =+PMGR!BJ9+BP!BJ9 -> 0 | BK9: =+PMGR!BK9+BP!BK9 -> 0 | BL9: =+PMGR!BL9+BP!BL9 -> 0 | ... BP9: =+PMGR!BP9+BP!BP9 -> 0 | BQ9: =+SUM(BE9:BP9) -> 0 | BS9: =+PMGR!BS9+BP!BS9 -> 0 | BT9: =+PMGR!BT9+BP!BT9 -> 0 | BU9: =+PMGR!BU9+BP!BU9 -> 0 | BV9: =+PMGR!BV9+BP!BV9 -> 0 | BW9: =+PMGR!BW9+BP!BW9 -> 0 | BX9: =+PMGR!BX9+BP!BX9 -> 0 | BY9: =+PMGR!BY9+BP!BY9 -> 0 | BZ9: =+PMGR!BZ9+BP!BZ9 -> 0 | ... CD9: =+PMGR!CD9+BP!CD9 -> 0 | CE9: =+SUM(BS9:CD9) -> 0 | CG9: =+PMGR!CG9+BP!CG9 -> 0 | CH9: =+PMGR!CH9+BP!CH9 -> 0 | CI9: =+PMGR!CI9+BP!CI9 -> 0 | CJ9: =+PMGR!CJ9+BP!CJ9 -> 0 | CK9: =+PMGR!CK9+BP!CK9 -> 0 | CL9: =+PMGR!CL9+BP!CL9 -> 0 | CM9: =+PMGR!CM9+BP!CM9 -> 0 | CN9: =+PMGR!CN9+BP!CN9 -> 0 | ... CR9: =+PMGR!CR9+BP!CR9 -> 0 | CS9: =+SUM(CG9:CR9) -> 0 | CT9: Sales Target Bonus | CU9: =+PMGR!CU9+BP!CU9 -> 0 | CV9: =+PMGR!CV9+BP!CV9 -> 0 | CW9: =+PMGR!CW9+BP!CW9 -> 0 | CX9: =+PMGR!CX9+BP!CX9 -> 0 | CY9: =+PMGR!CY9+BP!CY9 -> 0 | CZ9: =+PMGR!CZ9+BP!CZ9 -> 0 | DA9: =+PMGR!DA9+BP!DA9 -> 0 | DB9: =+PMGR!DB9+BP!DB9 -> 0 | ... DF9: =+PMGR!DF9+BP!DF9 -> 0 | DG9: =+SUM(CU9:DF9) -> 0 | DI9: =+PMGR!DI9+BP!DI9 -> 0 | DJ9: =+PMGR!DJ9+BP!DJ9 -> 0 | DK9: =+PMGR!DK9+BP!DK9 -> 0 | DL9: =+PMGR!DL9+BP!DL9 -> 0 | DM9: =+PMGR!DM9+BP!DM9 -> 0 | DN9: =+PMGR!DN9+BP!DN9 -> 0 | DO9: =+PMGR!DO9+BP!DO9 -> 0 | DP9: =+PMGR!DP9+BP!DP9 -> 0 | ... DT9: =+PMGR!DT9+BP!DT9 -> 0 | DU9: =+SUM(DI9:DT9) -> 0 | DW9: =+PMGR!DW9+BP!DW9 -> 0 | DX9: =+PMGR!DX9+BP!DX9 -> 0 | DY9: =+PMGR!DY9+BP!DY9 -> 0 | DZ9: =+PMGR!DZ9+BP!DZ9 -> 0 | EA9: =+PMGR!EA9+BP!EA9 -> 0 | EB9: =+PMGR!EB9+BP!EB9 -> 0 | EC9: =+PMGR!EC9+BP!EC9 -> 0 | ED9: =+PMGR!ED9+BP!ED9 -> 0 | ... EH9: =+PMGR!EH9+BP!EH9 -> 0 | EI9: =+SUM(DW9:EH9) -> 0 | EJ9: Sales Target Bonus | EK9: =+PMGR!EK9+BP!EK9 -> 0 | EL9: =+PMGR!EL9+BP!EL9 -> 0 | EM9: =+PMGR!EM9+BP!EM9 -> 0 | EN9: =+PMGR!EN9+BP!EN9 -> 0 | EO9: =+PMGR!EO9+BP!EO9 -> 0 | EP9: =+PMGR!EP9+BP!EP9 -> 0 | EQ9: =+PMGR!EQ9+BP!EQ9 -> 0 | ER9: =+PMGR!ER9+BP!ER9 -> 0 | ... EV9: =+PMGR!EV9+BP!EV9 -> 0 | EW9: =+SUM(EK9:EV9) -> 0 | EY9: =+PMGR!EY9+BP!EY9 -> 0 | EZ9: =+PMGR!EZ9+BP!EZ9 -> 0 | FA9: =+PMGR!FA9+BP!FA9 -> 0 | FB9: =+PMGR!FB9+BP!FB9 -> 0 | FC9: =+PMGR!FC9+BP!FC9 -> 0 | FD9: =+PMGR!FD9+BP!FD9 -> 0 | FE9: =+PMGR!FE9+BP!FE9 -> 0 | FF9: =+PMGR!FF9+BP!FF9 -> 0 | ... FJ9: =+PMGR!FJ9+BP!FJ9 -> 0 | FK9: =+SUM(EY9:FJ9) -> 0
A10: =+AQ10+CG10+DW10 -> 0 | B10: =+AR10+CH10+DX10 -> 0 | C10: =+AS10+CI10+DY10 -> 0 | D10: =+AT10+CJ10+DZ10 -> 0 | E10: =+AU10+CK10+EA10 -> 0 | F10: =+AV10+CL10+EB10 -> 0 | G10: =+AW10+CM10+EC10 -> 0 | H10: =+AX10+CN10+ED10 -> 0 | ... L10: =+BB10+CR10+EH10 -> 0 | M10: =+SUM(A10:L10) -> 0 | N10: EV | O10: =+BE10+CU10+EK10 -> 0 | P10: =+BF10+CV10+EL10 -> 0 | Q10: =+BG10+CW10+EM10 -> 0 | R10: =+BH10+CX10+EN10 -> 0 | S10: =+BI10+CY10+EO10 -> 0 | T10: =+BJ10+CZ10+EP10 -> 0 | U10: =+BK10+DA10+EQ10 -> 0 | V10: =+BL10+DB10+ER10 -> 0 | ... Z10: =+BP10+DF10+EV10 -> 0 | AA10: =+SUM(O10:Z10) -> 0 | AC10: =+BS10+DI10+EY10 -> 0 | AD10: =+BT10+DJ10+EZ10 -> 0 | AE10: =+BU10+DK10+FA10 -> 0 | AF10: =+BV10+DL10+FB10 -> 0 | AG10: =+BW10+DM10+FC10 -> 0 | AH10: =+BX10+DN10+FD10 -> 0 | AI10: =+BY10+DO10+FE10 -> 0 | AJ10: =+BZ10+DP10+FF10 -> 0 | ... AN10: =+CD10+DT10+FJ10 -> 0 | AO10: =+SUM(AC10:AN10) -> 0 | AQ10: =+PMGR!AQ10+BP!AQ10 -> 0 | AR10: =+PMGR!AR10+BP!AR10 -> 0 | AS10: =+PMGR!AS10+BP!AS10 -> 0 | AT10: =+PMGR!AT10+BP!AT10 -> 0 | AU10: =+PMGR!AU10+BP!AU10 -> 0 | AV10: =+PMGR!AV10+BP!AV10 -> 0 | AW10: =+PMGR!AW10+BP!AW10 -> 0 | AX10: =+PMGR!AX10+BP!AX10 -> 0 | ... BB10: =+PMGR!BB10+BP!BB10 -> 0 | BC10: =+SUM(AQ10:BB10) -> 0 | BD10: EV | BE10: =+PMGR!BE10+BP!BE10 -> 0 | BF10: =+PMGR!BF10+BP!BF10 -> 0 | BG10: =+PMGR!BG10+BP!BG10 -> 0 | BH10: =+PMGR!BH10+BP!BH10 -> 0 | BI10: =+PMGR!BI10+BP!BI10 -> 0 | BJ10: =+PMGR!BJ10+BP!BJ10 -> 0 | BK10: =+PMGR!BK10+BP!BK10 -> 0 | BL10: =+PMGR!BL10+BP!BL10 -> 0 | ... BP10: =+PMGR!BP10+BP!BP10 -> 0 | BQ10: =+SUM(BE10:BP10) -> 0 | BS10: =+PMGR!BS10+BP!BS10 -> 0 | BT10: =+PMGR!BT10+BP!BT10 -> 0 | BU10: =+PMGR!BU10+BP!BU10 -> 0 | BV10: =+PMGR!BV10+BP!BV10 -> 0 | BW10: =+PMGR!BW10+BP!BW10 -> 0 | BX10: =+PMGR!BX10+BP!BX10 -> 0 | BY10: =+PMGR!BY10+BP!BY10 -> 0 | BZ10: =+PMGR!BZ10+BP!BZ10 -> 0 | ... CD10: =+PMGR!CD10+BP!CD10 -> 0 | CE10: =+SUM(BS10:CD10) -> 0 | CG10: =+PMGR!CG10+BP!CG10 -> 0 | CH10: =+PMGR!CH10+BP!CH10 -> 0 | CI10: =+PMGR!CI10+BP!CI10 -> 0 | CJ10: =+PMGR!CJ10+BP!CJ10 -> 0 | CK10: =+PMGR!CK10+BP!CK10 -> 0 | CL10: =+PMGR!CL10+BP!CL10 -> 0 | CM10: =+PMGR!CM10+BP!CM10 -> 0 | CN10: =+PMGR!CN10+BP!CN10 -> 0 | ... CR10: =+PMGR!CR10+BP!CR10 -> 0 | CS10: =+SUM(CG10:CR10) -> 0 | CT10: EV | CU10: =+PMGR!CU10+BP!CU10 -> 0 | CV10: =+PMGR!CV10+BP!CV10 -> 0 | CW10: =+PMGR!CW10+BP!CW10 -> 0 | CX10: =+PMGR!CX10+BP!CX10 -> 0 | CY10: =+PMGR!CY10+BP!CY10 -> 0 | CZ10: =+PMGR!CZ10+BP!CZ10 -> 0 | DA10: =+PMGR!DA10+BP!DA10 -> 0 | DB10: =+PMGR!DB10+BP!DB10 -> 0 | ... DF10: =+PMGR!DF10+BP!DF10 -> 0 | DG10: =+SUM(CU10:DF10) -> 0 | DI10: =+PMGR!DI10+BP!DI10 -> 0 | DJ10: =+PMGR!DJ10+BP!DJ10 -> 0 | DK10: =+PMGR!DK10+BP!DK10 -> 0 | DL10: =+PMGR!DL10+BP!DL10 -> 0 | DM10: =+PMGR!DM10+BP!DM10 -> 0 | DN10: =+PMGR!DN10+BP!DN10 -> 0 | DO10: =+PMGR!DO10+BP!DO10 -> 0 | DP10: =+PMGR!DP10+BP!DP10 -> 0 | ... DT10: =+PMGR!DT10+BP!DT10 -> 0 | DU10: =+SUM(DI10:DT10) -> 0 | DW10: =+PMGR!DW10+BP!DW10 -> 0 | DX10: =+PMGR!DX10+BP!DX10 -> 0 | DY10: =+PMGR!DY10+BP!DY10 -> 0 | DZ10: =+PMGR!DZ10+BP!DZ10 -> 0 | EA10: =+PMGR!EA10+BP!EA10 -> 0 | EB10: =+PMGR!EB10+BP!EB10 -> 0 | EC10: =+PMGR!EC10+BP!EC10 -> 0 | ED10: =+PMGR!ED10+BP!ED10 -> 0 | ... EH10: =+PMGR!EH10+BP!EH10 -> 0 | EI10: =+SUM(DW10:EH10) -> 0 | EJ10: EV | EK10: =+PMGR!EK10+BP!EK10 -> 0 | EL10: =+PMGR!EL10+BP!EL10 -> 0 | EM10: =+PMGR!EM10+BP!EM10 -> 0 | EN10: =+PMGR!EN10+BP!EN10 -> 0 | EO10: =+PMGR!EO10+BP!EO10 -> 0 | EP10: =+PMGR!EP10+BP!EP10 -> 0 | EQ10: =+PMGR!EQ10+BP!EQ10 -> 0 | ER10: =+PMGR!ER10+BP!ER10 -> 0 | ... EV10: =+PMGR!EV10+BP!EV10 -> 0 | EW10: =+SUM(EK10:EV10) -> 0 | EY10: =+PMGR!EY10+BP!EY10 -> 0 | EZ10: =+PMGR!EZ10+BP!EZ10 -> 0 | FA10: =+PMGR!FA10+BP!FA10 -> 0 | FB10: =+PMGR!FB10+BP!FB10 -> 0 | FC10: =+PMGR!FC10+BP!FC10 -> 0 | FD10: =+PMGR!FD10+BP!FD10 -> 0 | FE10: =+PMGR!FE10+BP!FE10 -> 0 | FF10: =+PMGR!FF10+BP!FF10 -> 0 | ... FJ10: =+PMGR!FJ10+BP!FJ10 -> 0 | FK10: =+SUM(EY10:FJ10) -> 0
A11: =+AQ11+CG11+DW11 -> 0 | B11: =+AR11+CH11+DX11 -> 0 | C11: =+AS11+CI11+DY11 -> 0 | D11: =+AT11+CJ11+DZ11 -> 0 | E11: =+AU11+CK11+EA11 -> 0 | F11: =+AV11+CL11+EB11 -> 0 | G11: =+AW11+CM11+EC11 -> 0 | H11: =+AX11+CN11+ED11 -> 0 | ... L11: =+BB11+CR11+EH11 -> 0 | M11: =+SUM(A11:L11) -> 0 | N11: TEV | O11: =+BE11+CU11+EK11 -> 0 | P11: =+BF11+CV11+EL11 -> 0 | Q11: =+BG11+CW11+EM11 -> 0 | R11: =+BH11+CX11+EN11 -> 0 | S11: =+BI11+CY11+EO11 -> 0 | T11: =+BJ11+CZ11+EP11 -> 0 | U11: =+BK11+DA11+EQ11 -> 0 | V11: =+BL11+DB11+ER11 -> 0 | ... Z11: =+BP11+DF11+EV11 -> 0 | AA11: =+SUM(O11:Z11) -> 0 | AC11: =+BS11+DI11+EY11 -> 0 | AD11: =+BT11+DJ11+EZ11 -> 0 | AE11: =+BU11+DK11+FA11 -> 0 | AF11: =+BV11+DL11+FB11 -> 0 | AG11: =+BW11+DM11+FC11 -> 0 | AH11: =+BX11+DN11+FD11 -> 0 | AI11: =+BY11+DO11+FE11 -> 0 | AJ11: =+BZ11+DP11+FF11 -> 0 | ... AN11: =+CD11+DT11+FJ11 -> 0 | AO11: =+SUM(AC11:AN11) -> 0 | AQ11: =+PMGR!AQ11+BP!AQ11 -> 0 | AR11: =+PMGR!AR11+BP!AR11 -> 0 | AS11: =+PMGR!AS11+BP!AS11 -> 0 | AT11: =+PMGR!AT11+BP!AT11 -> 0 | AU11: =+PMGR!AU11+BP!AU11 -> 0 | AV11: =+PMGR!AV11+BP!AV11 -> 0 | AW11: =+PMGR!AW11+BP!AW11 -> 0 | AX11: =+PMGR!AX11+BP!AX11 -> 0 | ... BB11: =+PMGR!BB11+BP!BB11 -> 0 | BC11: =+SUM(AQ11:BB11) -> 0 | BD11: TEV | BE11: =+PMGR!BE11+BP!BE11 -> 0 | BF11: =+PMGR!BF11+BP!BF11 -> 0 | BG11: =+PMGR!BG11+BP!BG11 -> 0 | BH11: =+PMGR!BH11+BP!BH11 -> 0 | BI11: =+PMGR!BI11+BP!BI11 -> 0 | BJ11: =+PMGR!BJ11+BP!BJ11 -> 0 | BK11: =+PMGR!BK11+BP!BK11 -> 0 | BL11: =+PMGR!BL11+BP!BL11 -> 0 | ... BP11: =+PMGR!BP11+BP!BP11 -> 0 | BQ11: =+SUM(BE11:BP11) -> 0 | BS11: =+PMGR!BS11+BP!BS11 -> 0 | BT11: =+PMGR!BT11+BP!BT11 -> 0 | BU11: =+PMGR!BU11+BP!BU11 -> 0 | BV11: =+PMGR!BV11+BP!BV11 -> 0 | BW11: =+PMGR!BW11+BP!BW11 -> 0 | BX11: =+PMGR!BX11+BP!BX11 -> 0 | BY11: =+PMGR!BY11+BP!BY11 -> 0 | BZ11: =+PMGR!BZ11+BP!BZ11 -> 0 | ... CD11: =+PMGR!CD11+BP!CD11 -> 0 | CE11: =+SUM(BS11:CD11) -> 0 | CG11: =+PMGR!CG11+BP!CG11 -> 0 | CH11: =+PMGR!CH11+BP!CH11 -> 0 | CI11: =+PMGR!CI11+BP!CI11 -> 0 | CJ11: =+PMGR!CJ11+BP!CJ11 -> 0 | CK11: =+PMGR!CK11+BP!CK11 -> 0 | CL11: =+PMGR!CL11+BP!CL11 -> 0 | CM11: =+PMGR!CM11+BP!CM11 -> 0 | CN11: =+PMGR!CN11+BP!CN11 -> 0 | ... CR11: =+PMGR!CR11+BP!CR11 -> 0 | CS11: =+SUM(CG11:CR11) -> 0 | CT11: TEV | CU11: =+PMGR!CU11+BP!CU11 -> 0 | CV11: =+PMGR!CV11+BP!CV11 -> 0 | CW11: =+PMGR!CW11+BP!CW11 -> 0 | CX11: =+PMGR!CX11+BP!CX11 -> 0 | CY11: =+PMGR!CY11+BP!CY11 -> 0 | CZ11: =+PMGR!CZ11+BP!CZ11 -> 0 | DA11: =+PMGR!DA11+BP!DA11 -> 0 | DB11: =+PMGR!DB11+BP!DB11 -> 0 | ... DF11: =+PMGR!DF11+BP!DF11 -> 0 | DG11: =+SUM(CU11:DF11) -> 0 | DI11: =+PMGR!DI11+BP!DI11 -> 0 | DJ11: =+PMGR!DJ11+BP!DJ11 -> 0 | DK11: =+PMGR!DK11+BP!DK11 -> 0 | DL11: =+PMGR!DL11+BP!DL11 -> 0 | DM11: =+PMGR!DM11+BP!DM11 -> 0 | DN11: =+PMGR!DN11+BP!DN11 -> 0 | DO11: =+PMGR!DO11+BP!DO11 -> 0 | DP11: =+PMGR!DP11+BP!DP11 -> 0 | ... DT11: =+PMGR!DT11+BP!DT11 -> 0 | DU11: =+SUM(DI11:DT11) -> 0 | DW11: =+PMGR!DW11+BP!DW11 -> 0 | DX11: =+PMGR!DX11+BP!DX11 -> 0 | DY11: =+PMGR!DY11+BP!DY11 -> 0 | DZ11: =+PMGR!DZ11+BP!DZ11 -> 0 | EA11: =+PMGR!EA11+BP!EA11 -> 0 | EB11: =+PMGR!EB11+BP!EB11 -> 0 | EC11: =+PMGR!EC11+BP!EC11 -> 0 | ED11: =+PMGR!ED11+BP!ED11 -> 0 | ... EH11: =+PMGR!EH11+BP!EH11 -> 0 | EI11: =+SUM(DW11:EH11) -> 0 | EJ11: TEV | EK11: =+PMGR!EK11+BP!EK11 -> 0 | EL11: =+PMGR!EL11+BP!EL11 -> 0 | EM11: =+PMGR!EM11+BP!EM11 -> 0 | EN11: =+PMGR!EN11+BP!EN11 -> 0 | EO11: =+PMGR!EO11+BP!EO11 -> 0 | EP11: =+PMGR!EP11+BP!EP11 -> 0 | EQ11: =+PMGR!EQ11+BP!EQ11 -> 0 | ER11: =+PMGR!ER11+BP!ER11 -> 0 | ... EV11: =+PMGR!EV11+BP!EV11 -> 0 | EW11: =+SUM(EK11:EV11) -> 0 | EY11: =+PMGR!EY11+BP!EY11 -> 0 | EZ11: =+PMGR!EZ11+BP!EZ11 -> 0 | FA11: =+PMGR!FA11+BP!FA11 -> 0 | FB11: =+PMGR!FB11+BP!FB11 -> 0 | FC11: =+PMGR!FC11+BP!FC11 -> 0 | FD11: =+PMGR!FD11+BP!FD11 -> 0 | FE11: =+PMGR!FE11+BP!FE11 -> 0 | FF11: =+PMGR!FF11+BP!FF11 -> 0 | ... FJ11: =+PMGR!FJ11+BP!FJ11 -> 0 | FK11: =+SUM(EY11:FJ11) -> 0
A12: =+AQ12+CG12+DW12 -> 0 | B12: =+AR12+CH12+DX12 -> 0 | C12: =+AS12+CI12+DY12 -> 0 | D12: =+AT12+CJ12+DZ12 -> 0 | E12: =+AU12+CK12+EA12 -> 0 | F12: =+AV12+CL12+EB12 -> 0 | G12: =+AW12+CM12+EC12 -> 0 | H12: =+AX12+CN12+ED12 -> 0 | ... L12: =+BB12+CR12+EH12 -> 0 | M12: =+SUM(A12:L12) -> 0 | N12: Market Share Bonus | O12: =+BE12+CU12+EK12 -> 0 | P12: =+BF12+CV12+EL12 -> 0 | Q12: =+BG12+CW12+EM12 -> 0 | R12: =+BH12+CX12+EN12 -> 0 | S12: =+BI12+CY12+EO12 -> 0 | T12: =+BJ12+CZ12+EP12 -> 0 | U12: =+BK12+DA12+EQ12 -> 0 | V12: =+BL12+DB12+ER12 -> 0 | ... Z12: =+BP12+DF12+EV12 -> 0 | AA12: =+SUM(O12:Z12) -> 0 | AC12: =+BS12+DI12+EY12 -> 0 | AD12: =+BT12+DJ12+EZ12 -> 0 | AE12: =+BU12+DK12+FA12 -> 0 | AF12: =+BV12+DL12+FB12 -> 0 | AG12: =+BW12+DM12+FC12 -> 0 | AH12: =+BX12+DN12+FD12 -> 0 | AI12: =+BY12+DO12+FE12 -> 0 | AJ12: =+BZ12+DP12+FF12 -> 0 | ... AN12: =+CD12+DT12+FJ12 -> 0 | AO12: =+SUM(AC12:AN12) -> 0 | AQ12: =+PMGR!AQ12+BP!AQ12 -> 0 | AR12: =+PMGR!AR12+BP!AR12 -> 0 | AS12: =+PMGR!AS12+BP!AS12 -> 0 | AT12: =+PMGR!AT12+BP!AT12 -> 0 | AU12: =+PMGR!AU12+BP!AU12 -> 0 | AV12: =+PMGR!AV12+BP!AV12 -> 0 | AW12: =+PMGR!AW12+BP!AW12 -> 0 | AX12: =+PMGR!AX12+BP!AX12 -> 0 | ... BB12: =+PMGR!BB12+BP!BB12 -> 0 | BC12: =+SUM(AQ12:BB12) -> 0 | BD12: Market Share Bonus | BE12: =+PMGR!BE12+BP!BE12 -> 0 | BF12: =+PMGR!BF12+BP!BF12 -> 0 | BG12: =+PMGR!BG12+BP!BG12 -> 0 | BH12: =+PMGR!BH12+BP!BH12 -> 0 | BI12: =+PMGR!BI12+BP!BI12 -> 0 | BJ12: =+PMGR!BJ12+BP!BJ12 -> 0 | BK12: =+PMGR!BK12+BP!BK12 -> 0 | BL12: =+PMGR!BL12+BP!BL12 -> 0 | ... BP12: =+PMGR!BP12+BP!BP12 -> 0 | BQ12: =+SUM(BE12:BP12) -> 0 | BS12: =+PMGR!BS12+BP!BS12 -> 0 | BT12: =+PMGR!BT12+BP!BT12 -> 0 | BU12: =+PMGR!BU12+BP!BU12 -> 0 | BV12: =+PMGR!BV12+BP!BV12 -> 0 | BW12: =+PMGR!BW12+BP!BW12 -> 0 | BX12: =+PMGR!BX12+BP!BX12 -> 0 | BY12: =+PMGR!BY12+BP!BY12 -> 0 | BZ12: =+PMGR!BZ12+BP!BZ12 -> 0 | ... CD12: =+PMGR!CD12+BP!CD12 -> 0 | CE12: =+SUM(BS12:CD12) -> 0 | CG12: =+PMGR!CG12+BP!CG12 -> 0 | CH12: =+PMGR!CH12+BP!CH12 -> 0 | CI12: =+PMGR!CI12+BP!CI12 -> 0 | CJ12: =+PMGR!CJ12+BP!CJ12 -> 0 | CK12: =+PMGR!CK12+BP!CK12 -> 0 | CL12: =+PMGR!CL12+BP!CL12 -> 0 | CM12: =+PMGR!CM12+BP!CM12 -> 0 | CN12: =+PMGR!CN12+BP!CN12 -> 0 | ... CR12: =+PMGR!CR12+BP!CR12 -> 0 | CS12: =+SUM(CG12:CR12) -> 0 | CT12: Market Share Bonus | CU12: =+PMGR!CU12+BP!CU12 -> 0 | CV12: =+PMGR!CV12+BP!CV12 -> 0 | CW12: =+PMGR!CW12+BP!CW12 -> 0 | CX12: =+PMGR!CX12+BP!CX12 -> 0 | CY12: =+PMGR!CY12+BP!CY12 -> 0 | CZ12: =+PMGR!CZ12+BP!CZ12 -> 0 | DA12: =+PMGR!DA12+BP!DA12 -> 0 | DB12: =+PMGR!DB12+BP!DB12 -> 0 | ... DF12: =+PMGR!DF12+BP!DF12 -> 0 | DG12: =+SUM(CU12:DF12) -> 0 | DI12: =+PMGR!DI12+BP!DI12 -> 0 | DJ12: =+PMGR!DJ12+BP!DJ12 -> 0 | DK12: =+PMGR!DK12+BP!DK12 -> 0 | DL12: =+PMGR!DL12+BP!DL12 -> 0 | DM12: =+PMGR!DM12+BP!DM12 -> 0 | DN12: =+PMGR!DN12+BP!DN12 -> 0 | DO12: =+PMGR!DO12+BP!DO12 -> 0 | DP12: =+PMGR!DP12+BP!DP12 -> 0 | ... DT12: =+PMGR!DT12+BP!DT12 -> 0 | DU12: =+SUM(DI12:DT12) -> 0 | DW12: =+PMGR!DW12+BP!DW12 -> 0 | DX12: =+PMGR!DX12+BP!DX12 -> 0 | DY12: =+PMGR!DY12+BP!DY12 -> 0 | DZ12: =+PMGR!DZ12+BP!DZ12 -> 0 | EA12: =+PMGR!EA12+BP!EA12 -> 0 | EB12: =+PMGR!EB12+BP!EB12 -> 0 | EC12: =+PMGR!EC12+BP!EC12 -> 0 | ED12: =+PMGR!ED12+BP!ED12 -> 0 | ... EH12: =+PMGR!EH12+BP!EH12 -> 0 | EI12: =+SUM(DW12:EH12) -> 0 | EJ12: Market Share Bonus | EK12: =+PMGR!EK12+BP!EK12 -> 0 | EL12: =+PMGR!EL12+BP!EL12 -> 0 | EM12: =+PMGR!EM12+BP!EM12 -> 0 | EN12: =+PMGR!EN12+BP!EN12 -> 0 | EO12: =+PMGR!EO12+BP!EO12 -> 0 | EP12: =+PMGR!EP12+BP!EP12 -> 0 | EQ12: =+PMGR!EQ12+BP!EQ12 -> 0 | ER12: =+PMGR!ER12+BP!ER12 -> 0 | ... EV12: =+PMGR!EV12+BP!EV12 -> 0 | EW12: =+SUM(EK12:EV12) -> 0 | EY12: =+PMGR!EY12+BP!EY12 -> 0 | EZ12: =+PMGR!EZ12+BP!EZ12 -> 0 | FA12: =+PMGR!FA12+BP!FA12 -> 0 | FB12: =+PMGR!FB12+BP!FB12 -> 0 | FC12: =+PMGR!FC12+BP!FC12 -> 0 | FD12: =+PMGR!FD12+BP!FD12 -> 0 | FE12: =+PMGR!FE12+BP!FE12 -> 0 | FF12: =+PMGR!FF12+BP!FF12 -> 0 | ... FJ12: =+PMGR!FJ12+BP!FJ12 -> 0 | FK12: =+SUM(EY12:FJ12) -> 0
A13: =+SUM(A14:A17) -> 0 | B13: =+SUM(B14:B17) -> 0 | C13: =+SUM(C14:C17) -> 0 | D13: =+SUM(D14:D17) -> 0 | E13: =+SUM(E14:E17) -> 0 | F13: =+SUM(F14:F17) -> 0 | G13: =+SUM(G14:G17) -> 0 | H13: =+SUM(H14:H17) -> 0 | ... L13: =+SUM(L14:L17) -> 0 | M13: =+SUM(A13:L13) -> 0 | N13: Quantitative Margin | O13: =+SUM(O14:O17) -> 0 | P13: =+SUM(P14:P17) -> 0 | Q13: =+SUM(Q14:Q17) -> 0 | R13: =+SUM(R14:R17) -> 0 | S13: =+SUM(S14:S17) -> 0 | T13: =+SUM(T14:T17) -> 0 | U13: =+SUM(U14:U17) -> 0 | V13: =+SUM(V14:V17) -> 0 | ... Z13: =+SUM(Z14:Z17) -> 0 | AA13: =+SUM(O13:Z13) -> 0 | AC13: =+SUM(AC14:AC17) -> 0 | AD13: =+SUM(AD14:AD17) -> 0 | AE13: =+SUM(AE14:AE17) -> 0 | AF13: =+SUM(AF14:AF17) -> 0 | AG13: =+SUM(AG14:AG17) -> 0 | AH13: =+SUM(AH14:AH17) -> 0 | AI13: =+SUM(AI14:AI17) -> 0 | AJ13: =+SUM(AJ14:AJ17) -> 0 | ... AN13: =+SUM(AN14:AN17) -> 0 | AO13: =+SUM(AC13:AN13) -> 0 | AQ13: =+SUM(AQ14:AQ17) -> 0 | AR13: =+SUM(AR14:AR17) -> 0 | AS13: =+SUM(AS14:AS17) -> 0 | AT13: =+SUM(AT14:AT17) -> 0 | AU13: =+SUM(AU14:AU17) -> 0 | AV13: =+SUM(AV14:AV17) -> 0 | AW13: =+SUM(AW14:AW17) -> 0 | AX13: =+SUM(AX14:AX17) -> 0 | ... BB13: =+SUM(BB14:BB17) -> 0 | BC13: =+SUM(AQ13:BB13) -> 0 | BD13: =N13 -> Quantitative Margin | BE13: =+SUM(BE14:BE17) -> 0 | BF13: =+SUM(BF14:BF17) -> 0 | BG13: =+SUM(BG14:BG17) -> 0 | BH13: =+SUM(BH14:BH17) -> 0 | BI13: =+SUM(BI14:BI17) -> 0 | BJ13: =+SUM(BJ14:BJ17) -> 0 | BK13: =+SUM(BK14:BK17) -> 0 | BL13: =+SUM(BL14:BL17) -> 0 | ... BP13: =+SUM(BP14:BP17) -> 0 | BQ13: =+SUM(BE13:BP13) -> 0 | BS13: =+SUM(BS14:BS17) -> 0 | BT13: =+SUM(BT14:BT17) -> 0 | BU13: =+SUM(BU14:BU17) -> 0 | BV13: =+SUM(BV14:BV17) -> 0 | BW13: =+SUM(BW14:BW17) -> 0 | BX13: =+SUM(BX14:BX17) -> 0 | BY13: =+SUM(BY14:BY17) -> 0 | BZ13: =+SUM(BZ14:BZ17) -> 0 | ... CD13: =+SUM(CD14:CD17) -> 0 | CE13: =+SUM(BS13:CD13) -> 0 | CG13: =+SUM(CG14:CG17) -> 0 | CH13: =+SUM(CH14:CH17) -> 0 | CI13: =+SUM(CI14:CI17) -> 0 | CJ13: =+SUM(CJ14:CJ17) -> 0 | CK13: =+SUM(CK14:CK17) -> 0 | CL13: =+SUM(CL14:CL17) -> 0 | CM13: =+SUM(CM14:CM17) -> 0 | CN13: =+SUM(CN14:CN17) -> 0 | ... CR13: =+SUM(CR14:CR17) -> 0 | CS13: =+SUM(CG13:CR13) -> 0 | CT13: =BD13 -> Quantitative Margin | CU13: =+SUM(CU14:CU17) -> 0 | CV13: =+SUM(CV14:CV17) -> 0 | CW13: =+SUM(CW14:CW17) -> 0 | CX13: =+SUM(CX14:CX17) -> 0 | CY13: =+SUM(CY14:CY17) -> 0 | CZ13: =+SUM(CZ14:CZ17) -> 0 | DA13: =+SUM(DA14:DA17) -> 0 | DB13: =+SUM(DB14:DB17) -> 0 | ... DF13: =+SUM(DF14:DF17) -> 0 | DG13: =+SUM(CU13:DF13) -> 0 | DI13: =+SUM(DI14:DI17) -> 0 | DJ13: =+SUM(DJ14:DJ17) -> 0 | DK13: =+SUM(DK14:DK17) -> 0 | DL13: =+SUM(DL14:DL17) -> 0 | DM13: =+SUM(DM14:DM17) -> 0 | DN13: =+SUM(DN14:DN17) -> 0 | DO13: =+SUM(DO14:DO17) -> 0 | DP13: =+SUM(DP14:DP17) -> 0 | ... DT13: =+SUM(DT14:DT17) -> 0 | DU13: =+SUM(DI13:DT13) -> 0 | DW13: =+SUM(DW14:DW17) -> 0 | DX13: =+SUM(DX14:DX17) -> 0 | DY13: =+SUM(DY14:DY17) -> 0 | DZ13: =+SUM(DZ14:DZ17) -> 0 | EA13: =+SUM(EA14:EA17) -> 0 | EB13: =+SUM(EB14:EB17) -> 0 | EC13: =+SUM(EC14:EC17) -> 0 | ED13: =+SUM(ED14:ED17) -> 0 | ... EH13: =+SUM(EH14:EH17) -> 0 | EI13: =+SUM(DW13:EH13) -> 0 | EJ13: =CT13 -> Quantitative Margin | EK13: =+SUM(EK14:EK17) -> 0 | EL13: =+SUM(EL14:EL17) -> 0 | EM13: =+SUM(EM14:EM17) -> 0 | EN13: =+SUM(EN14:EN17) -> 0 | EO13: =+SUM(EO14:EO17) -> 0 | EP13: =+SUM(EP14:EP17) -> 0 | EQ13: =+SUM(EQ14:EQ17) -> 0 | ER13: =+SUM(ER14:ER17) -> 0 | ... EV13: =+SUM(EV14:EV17) -> 0 | EW13: =+SUM(EK13:EV13) -> 0 | EY13: =+SUM(EY14:EY17) -> 0 | EZ13: =+SUM(EZ14:EZ17) -> 0 | FA13: =+SUM(FA14:FA17) -> 0 | FB13: =+SUM(FB14:FB17) -> 0 | FC13: =+SUM(FC14:FC17) -> 0 | FD13: =+SUM(FD14:FD17) -> 0 | FE13: =+SUM(FE14:FE17) -> 0 | FF13: =+SUM(FF14:FF17) -> 0 | ... FJ13: =+SUM(FJ14:FJ17) -> 0 | FK13: =+SUM(EY13:FJ13) -> 0
A14: =+AQ14+CG14+DW14 -> 0 | B14: =+AR14+CH14+DX14 -> 0 | C14: =+AS14+CI14+DY14 -> 0 | D14: =+AT14+CJ14+DZ14 -> 0 | E14: =+AU14+CK14+EA14 -> 0 | F14: =+AV14+CL14+EB14 -> 0 | G14: =+AW14+CM14+EC14 -> 0 | H14: =+AX14+CN14+ED14 -> 0 | ... L14: =+BB14+CR14+EH14 -> 0 | M14: =+SUM(A14:L14) -> 0 | N14: Digital and Lead Management | O14: =+BE14+CU14+EK14 -> 0 | P14: =+BF14+CV14+EL14 -> 0 | Q14: =+BG14+CW14+EM14 -> 0 | R14: =+BH14+CX14+EN14 -> 0 | S14: =+BI14+CY14+EO14 -> 0 | T14: =+BJ14+CZ14+EP14 -> 0 | U14: =+BK14+DA14+EQ14 -> 0 | V14: =+BL14+DB14+ER14 -> 0 | ... Z14: =+BP14+DF14+EV14 -> 0 | AA14: =+SUM(O14:Z14) -> 0 | AC14: =+BS14+DI14+EY14 -> 0 | AD14: =+BT14+DJ14+EZ14 -> 0 | AE14: =+BU14+DK14+FA14 -> 0 | AF14: =+BV14+DL14+FB14 -> 0 | AG14: =+BW14+DM14+FC14 -> 0 | AH14: =+BX14+DN14+FD14 -> 0 | AI14: =+BY14+DO14+FE14 -> 0 | AJ14: =+BZ14+DP14+FF14 -> 0 | ... AN14: =+CD14+DT14+FJ14 -> 0 | AO14: =+SUM(AC14:AN14) -> 0 | AQ14: =+PMGR!AQ14+BP!AQ14 -> 0 | AR14: =+PMGR!AR14+BP!AR14 -> 0 | AS14: =+PMGR!AS14+BP!AS14 -> 0 | AT14: =+PMGR!AT14+BP!AT14 -> 0 | AU14: =+PMGR!AU14+BP!AU14 -> 0 | AV14: =+PMGR!AV14+BP!AV14 -> 0 | AW14: =+PMGR!AW14+BP!AW14 -> 0 | AX14: =+PMGR!AX14+BP!AX14 -> 0 | ... BB14: =+PMGR!BB14+BP!BB14 -> 0 | BC14: =+SUM(AQ14:BB14) -> 0 | BD14: =N14 -> Digital and Lead Management | BE14: =+PMGR!BE14+BP!BE14 -> 0 | BF14: =+PMGR!BF14+BP!BF14 -> 0 | BG14: =+PMGR!BG14+BP!BG14 -> 0 | BH14: =+PMGR!BH14+BP!BH14 -> 0 | BI14: =+PMGR!BI14+BP!BI14 -> 0 | BJ14: =+PMGR!BJ14+BP!BJ14 -> 0 | BK14: =+PMGR!BK14+BP!BK14 -> 0 | BL14: =+PMGR!BL14+BP!BL14 -> 0 | ... BP14: =+PMGR!BP14+BP!BP14 -> 0 | BQ14: =+SUM(BE14:BP14) -> 0 | BS14: =+PMGR!BS14+BP!BS14 -> 0 | BT14: =+PMGR!BT14+BP!BT14 -> 0 | BU14: =+PMGR!BU14+BP!BU14 -> 0 | BV14: =+PMGR!BV14+BP!BV14 -> 0 | BW14: =+PMGR!BW14+BP!BW14 -> 0 | BX14: =+PMGR!BX14+BP!BX14 -> 0 | BY14: =+PMGR!BY14+BP!BY14 -> 0 | BZ14: =+PMGR!BZ14+BP!BZ14 -> 0 | ... CD14: =+PMGR!CD14+BP!CD14 -> 0 | CE14: =+SUM(BS14:CD14) -> 0 | CG14: =+PMGR!CG14+BP!CG14 -> 0 | CH14: =+PMGR!CH14+BP!CH14 -> 0 | CI14: =+PMGR!CI14+BP!CI14 -> 0 | CJ14: =+PMGR!CJ14+BP!CJ14 -> 0 | CK14: =+PMGR!CK14+BP!CK14 -> 0 | CL14: =+PMGR!CL14+BP!CL14 -> 0 | CM14: =+PMGR!CM14+BP!CM14 -> 0 | CN14: =+PMGR!CN14+BP!CN14 -> 0 | ... CR14: =+PMGR!CR14+BP!CR14 -> 0 | CS14: =+SUM(CG14:CR14) -> 0 | CT14: =BD14 -> Digital and Lead Management | CU14: =+PMGR!CU14+BP!CU14 -> 0 | CV14: =+PMGR!CV14+BP!CV14 -> 0 | CW14: =+PMGR!CW14+BP!CW14 -> 0 | CX14: =+PMGR!CX14+BP!CX14 -> 0 | CY14: =+PMGR!CY14+BP!CY14 -> 0 | CZ14: =+PMGR!CZ14+BP!CZ14 -> 0 | DA14: =+PMGR!DA14+BP!DA14 -> 0 | DB14: =+PMGR!DB14+BP!DB14 -> 0 | ... DF14: =+PMGR!DF14+BP!DF14 -> 0 | DG14: =+SUM(CU14:DF14) -> 0 | DI14: =+PMGR!DI14+BP!DI14 -> 0 | DJ14: =+PMGR!DJ14+BP!DJ14 -> 0 | DK14: =+PMGR!DK14+BP!DK14 -> 0 | DL14: =+PMGR!DL14+BP!DL14 -> 0 | DM14: =+PMGR!DM14+BP!DM14 -> 0 | DN14: =+PMGR!DN14+BP!DN14 -> 0 | DO14: =+PMGR!DO14+BP!DO14 -> 0 | DP14: =+PMGR!DP14+BP!DP14 -> 0 | ... DT14: =+PMGR!DT14+BP!DT14 -> 0 | DU14: =+SUM(DI14:DT14) -> 0 | DW14: =+PMGR!DW14+BP!DW14 -> 0 | DX14: =+PMGR!DX14+BP!DX14 -> 0 | DY14: =+PMGR!DY14+BP!DY14 -> 0 | DZ14: =+PMGR!DZ14+BP!DZ14 -> 0 | EA14: =+PMGR!EA14+BP!EA14 -> 0 | EB14: =+PMGR!EB14+BP!EB14 -> 0 | EC14: =+PMGR!EC14+BP!EC14 -> 0 | ED14: =+PMGR!ED14+BP!ED14 -> 0 | ... EH14: =+PMGR!EH14+BP!EH14 -> 0 | EI14: =+SUM(DW14:EH14) -> 0 | EJ14: =CT14 -> Digital and Lead Management | EK14: =+PMGR!EK14+BP!EK14 -> 0 | EL14: =+PMGR!EL14+BP!EL14 -> 0 | EM14: =+PMGR!EM14+BP!EM14 -> 0 | EN14: =+PMGR!EN14+BP!EN14 -> 0 | EO14: =+PMGR!EO14+BP!EO14 -> 0 | EP14: =+PMGR!EP14+BP!EP14 -> 0 | EQ14: =+PMGR!EQ14+BP!EQ14 -> 0 | ER14: =+PMGR!ER14+BP!ER14 -> 0 | ... EV14: =+PMGR!EV14+BP!EV14 -> 0 | EW14: =+SUM(EK14:EV14) -> 0 | EY14: =+PMGR!EY14+BP!EY14 -> 0 | EZ14: =+PMGR!EZ14+BP!EZ14 -> 0 | FA14: =+PMGR!FA14+BP!FA14 -> 0 | FB14: =+PMGR!FB14+BP!FB14 -> 0 | FC14: =+PMGR!FC14+BP!FC14 -> 0 | FD14: =+PMGR!FD14+BP!FD14 -> 0 | FE14: =+PMGR!FE14+BP!FE14 -> 0 | FF14: =+PMGR!FF14+BP!FF14 -> 0 | ... FJ14: =+PMGR!FJ14+BP!FJ14 -> 0 | FK14: =+SUM(EY14:FJ14) -> 0
A15: =+AQ15+CG15+DW15 -> 0 | B15: =+AR15+CH15+DX15 -> 0 | C15: =+AS15+CI15+DY15 -> 0 | D15: =+AT15+CJ15+DZ15 -> 0 | E15: =+AU15+CK15+EA15 -> 0 | F15: =+AV15+CL15+EB15 -> 0 | G15: =+AW15+CM15+EC15 -> 0 | H15: =+AX15+CN15+ED15 -> 0 | ... L15: =+BB15+CR15+EH15 -> 0 | M15: =+SUM(A15:L15) -> 0 | N15: Customer Experience | O15: =+BE15+CU15+EK15 -> 0 | P15: =+BF15+CV15+EL15 -> 0 | Q15: =+BG15+CW15+EM15 -> 0 | R15: =+BH15+CX15+EN15 -> 0 | S15: =+BI15+CY15+EO15 -> 0 | T15: =+BJ15+CZ15+EP15 -> 0 | U15: =+BK15+DA15+EQ15 -> 0 | V15: =+BL15+DB15+ER15 -> 0 | ... Z15: =+BP15+DF15+EV15 -> 0 | AA15: =+SUM(O15:Z15) -> 0 | AC15: =+BS15+DI15+EY15 -> 0 | AD15: =+BT15+DJ15+EZ15 -> 0 | AE15: =+BU15+DK15+FA15 -> 0 | AF15: =+BV15+DL15+FB15 -> 0 | AG15: =+BW15+DM15+FC15 -> 0 | AH15: =+BX15+DN15+FD15 -> 0 | AI15: =+BY15+DO15+FE15 -> 0 | AJ15: =+BZ15+DP15+FF15 -> 0 | ... AN15: =+CD15+DT15+FJ15 -> 0 | AO15: =+SUM(AC15:AN15) -> 0 | AQ15: =+PMGR!AQ15+BP!AQ15 -> 0 | AR15: =+PMGR!AR15+BP!AR15 -> 0 | AS15: =+PMGR!AS15+BP!AS15 -> 0 | AT15: =+PMGR!AT15+BP!AT15 -> 0 | AU15: =+PMGR!AU15+BP!AU15 -> 0 | AV15: =+PMGR!AV15+BP!AV15 -> 0 | AW15: =+PMGR!AW15+BP!AW15 -> 0 | AX15: =+PMGR!AX15+BP!AX15 -> 0 | ... BB15: =+PMGR!BB15+BP!BB15 -> 0 | BC15: =+SUM(AQ15:BB15) -> 0 | BD15: =N15 -> Customer Experience | BE15: =+PMGR!BE15+BP!BE15 -> 0 | BF15: =+PMGR!BF15+BP!BF15 -> 0 | BG15: =+PMGR!BG15+BP!BG15 -> 0 | BH15: =+PMGR!BH15+BP!BH15 -> 0 | BI15: =+PMGR!BI15+BP!BI15 -> 0 | BJ15: =+PMGR!BJ15+BP!BJ15 -> 0 | BK15: =+PMGR!BK15+BP!BK15 -> 0 | BL15: =+PMGR!BL15+BP!BL15 -> 0 | ... BP15: =+PMGR!BP15+BP!BP15 -> 0 | BQ15: =+SUM(BE15:BP15) -> 0 | BS15: =+PMGR!BS15+BP!BS15 -> 0 | BT15: =+PMGR!BT15+BP!BT15 -> 0 | BU15: =+PMGR!BU15+BP!BU15 -> 0 | BV15: =+PMGR!BV15+BP!BV15 -> 0 | BW15: =+PMGR!BW15+BP!BW15 -> 0 | BX15: =+PMGR!BX15+BP!BX15 -> 0 | BY15: =+PMGR!BY15+BP!BY15 -> 0 | BZ15: =+PMGR!BZ15+BP!BZ15 -> 0 | ... CD15: =+PMGR!CD15+BP!CD15 -> 0 | CE15: =+SUM(BS15:CD15) -> 0 | CG15: =+PMGR!CG15+BP!CG15 -> 0 | CH15: =+PMGR!CH15+BP!CH15 -> 0 | CI15: =+PMGR!CI15+BP!CI15 -> 0 | CJ15: =+PMGR!CJ15+BP!CJ15 -> 0 | CK15: =+PMGR!CK15+BP!CK15 -> 0 | CL15: =+PMGR!CL15+BP!CL15 -> 0 | CM15: =+PMGR!CM15+BP!CM15 -> 0 | CN15: =+PMGR!CN15+BP!CN15 -> 0 | ... CR15: =+PMGR!CR15+BP!CR15 -> 0 | CS15: =+SUM(CG15:CR15) -> 0 | CT15: =BD15 -> Customer Experience | CU15: =+PMGR!CU15+BP!CU15 -> 0 | CV15: =+PMGR!CV15+BP!CV15 -> 0 | CW15: =+PMGR!CW15+BP!CW15 -> 0 | CX15: =+PMGR!CX15+BP!CX15 -> 0 | CY15: =+PMGR!CY15+BP!CY15 -> 0 | CZ15: =+PMGR!CZ15+BP!CZ15 -> 0 | DA15: =+PMGR!DA15+BP!DA15 -> 0 | DB15: =+PMGR!DB15+BP!DB15 -> 0 | ... DF15: =+PMGR!DF15+BP!DF15 -> 0 | DG15: =+SUM(CU15:DF15) -> 0 | DI15: =+PMGR!DI15+BP!DI15 -> 0 | DJ15: =+PMGR!DJ15+BP!DJ15 -> 0 | DK15: =+PMGR!DK15+BP!DK15 -> 0 | DL15: =+PMGR!DL15+BP!DL15 -> 0 | DM15: =+PMGR!DM15+BP!DM15 -> 0 | DN15: =+PMGR!DN15+BP!DN15 -> 0 | DO15: =+PMGR!DO15+BP!DO15 -> 0 | DP15: =+PMGR!DP15+BP!DP15 -> 0 | ... DT15: =+PMGR!DT15+BP!DT15 -> 0 | DU15: =+SUM(DI15:DT15) -> 0 | DW15: =+PMGR!DW15+BP!DW15 -> 0 | DX15: =+PMGR!DX15+BP!DX15 -> 0 | DY15: =+PMGR!DY15+BP!DY15 -> 0 | DZ15: =+PMGR!DZ15+BP!DZ15 -> 0 | EA15: =+PMGR!EA15+BP!EA15 -> 0 | EB15: =+PMGR!EB15+BP!EB15 -> 0 | EC15: =+PMGR!EC15+BP!EC15 -> 0 | ED15: =+PMGR!ED15+BP!ED15 -> 0 | ... EH15: =+PMGR!EH15+BP!EH15 -> 0 | EI15: =+SUM(DW15:EH15) -> 0 | EJ15: =CT15 -> Customer Experience | EK15: =+PMGR!EK15+BP!EK15 -> 0 | EL15: =+PMGR!EL15+BP!EL15 -> 0 | EM15: =+PMGR!EM15+BP!EM15 -> 0 | EN15: =+PMGR!EN15+BP!EN15 -> 0 | EO15: =+PMGR!EO15+BP!EO15 -> 0 | EP15: =+PMGR!EP15+BP!EP15 -> 0 | EQ15: =+PMGR!EQ15+BP!EQ15 -> 0 | ER15: =+PMGR!ER15+BP!ER15 -> 0 | ... EV15: =+PMGR!EV15+BP!EV15 -> 0 | EW15: =+SUM(EK15:EV15) -> 0 | EY15: =+PMGR!EY15+BP!EY15 -> 0 | EZ15: =+PMGR!EZ15+BP!EZ15 -> 0 | FA15: =+PMGR!FA15+BP!FA15 -> 0 | FB15: =+PMGR!FB15+BP!FB15 -> 0 | FC15: =+PMGR!FC15+BP!FC15 -> 0 | FD15: =+PMGR!FD15+BP!FD15 -> 0 | FE15: =+PMGR!FE15+BP!FE15 -> 0 | FF15: =+PMGR!FF15+BP!FF15 -> 0 | ... FJ15: =+PMGR!FJ15+BP!FJ15 -> 0 | FK15: =+SUM(EY15:FJ15) -> 0
A16: =+AQ16+CG16+DW16 -> 0 | B16: =+AR16+CH16+DX16 -> 0 | C16: =+AS16+CI16+DY16 -> 0 | D16: =+AT16+CJ16+DZ16 -> 0 | E16: =+AU16+CK16+EA16 -> 0 | F16: =+AV16+CL16+EB16 -> 0 | G16: =+AW16+CM16+EC16 -> 0 | H16: =+AX16+CN16+ED16 -> 0 | ... L16: =+BB16+CR16+EH16 -> 0 | M16: =+SUM(A16:L16) -> 0 | N16: Marketing And Process Steering | O16: =+BE16+CU16+EK16 -> 0 | P16: =+BF16+CV16+EL16 -> 0 | Q16: =+BG16+CW16+EM16 -> 0 | R16: =+BH16+CX16+EN16 -> 0 | S16: =+BI16+CY16+EO16 -> 0 | T16: =+BJ16+CZ16+EP16 -> 0 | U16: =+BK16+DA16+EQ16 -> 0 | V16: =+BL16+DB16+ER16 -> 0 | ... Z16: =+BP16+DF16+EV16 -> 0 | AA16: =+SUM(O16:Z16) -> 0 | AC16: =+BS16+DI16+EY16 -> 0 | AD16: =+BT16+DJ16+EZ16 -> 0 | AE16: =+BU16+DK16+FA16 -> 0 | AF16: =+BV16+DL16+FB16 -> 0 | AG16: =+BW16+DM16+FC16 -> 0 | AH16: =+BX16+DN16+FD16 -> 0 | AI16: =+BY16+DO16+FE16 -> 0 | AJ16: =+BZ16+DP16+FF16 -> 0 | ... AN16: =+CD16+DT16+FJ16 -> 0 | AO16: =+SUM(AC16:AN16) -> 0 | AQ16: =+PMGR!AQ16+BP!AQ16 -> 0 | AR16: =+PMGR!AR16+BP!AR16 -> 0 | AS16: =+PMGR!AS16+BP!AS16 -> 0 | AT16: =+PMGR!AT16+BP!AT16 -> 0 | AU16: =+PMGR!AU16+BP!AU16 -> 0 | AV16: =+PMGR!AV16+BP!AV16 -> 0 | AW16: =+PMGR!AW16+BP!AW16 -> 0 | AX16: =+PMGR!AX16+BP!AX16 -> 0 | ... BB16: =+PMGR!BB16+BP!BB16 -> 0 | BC16: =+SUM(AQ16:BB16) -> 0 | BD16: =N16 -> Marketing And Process Steering | BE16: =+PMGR!BE16+BP!BE16 -> 0 | BF16: =+PMGR!BF16+BP!BF16 -> 0 | BG16: =+PMGR!BG16+BP!BG16 -> 0 | BH16: =+PMGR!BH16+BP!BH16 -> 0 | BI16: =+PMGR!BI16+BP!BI16 -> 0 | BJ16: =+PMGR!BJ16+BP!BJ16 -> 0 | BK16: =+PMGR!BK16+BP!BK16 -> 0 | BL16: =+PMGR!BL16+BP!BL16 -> 0 | ... BP16: =+PMGR!BP16+BP!BP16 -> 0 | BQ16: =+SUM(BE16:BP16) -> 0 | BS16: =+PMGR!BS16+BP!BS16 -> 0 | BT16: =+PMGR!BT16+BP!BT16 -> 0 | BU16: =+PMGR!BU16+BP!BU16 -> 0 | BV16: =+PMGR!BV16+BP!BV16 -> 0 | BW16: =+PMGR!BW16+BP!BW16 -> 0 | BX16: =+PMGR!BX16+BP!BX16 -> 0 | BY16: =+PMGR!BY16+BP!BY16 -> 0 | BZ16: =+PMGR!BZ16+BP!BZ16 -> 0 | ... CD16: =+PMGR!CD16+BP!CD16 -> 0 | CE16: =+SUM(BS16:CD16) -> 0 | CG16: =+PMGR!CG16+BP!CG16 -> 0 | CH16: =+PMGR!CH16+BP!CH16 -> 0 | CI16: =+PMGR!CI16+BP!CI16 -> 0 | CJ16: =+PMGR!CJ16+BP!CJ16 -> 0 | CK16: =+PMGR!CK16+BP!CK16 -> 0 | CL16: =+PMGR!CL16+BP!CL16 -> 0 | CM16: =+PMGR!CM16+BP!CM16 -> 0 | CN16: =+PMGR!CN16+BP!CN16 -> 0 | ... CR16: =+PMGR!CR16+BP!CR16 -> 0 | CS16: =+SUM(CG16:CR16) -> 0 | CT16: =BD16 -> Marketing And Process Steering | CU16: =+PMGR!CU16+BP!CU16 -> 0 | CV16: =+PMGR!CV16+BP!CV16 -> 0 | CW16: =+PMGR!CW16+BP!CW16 -> 0 | CX16: =+PMGR!CX16+BP!CX16 -> 0 | CY16: =+PMGR!CY16+BP!CY16 -> 0 | CZ16: =+PMGR!CZ16+BP!CZ16 -> 0 | DA16: =+PMGR!DA16+BP!DA16 -> 0 | DB16: =+PMGR!DB16+BP!DB16 -> 0 | ... DF16: =+PMGR!DF16+BP!DF16 -> 0 | DG16: =+SUM(CU16:DF16) -> 0 | DI16: =+PMGR!DI16+BP!DI16 -> 0 | DJ16: =+PMGR!DJ16+BP!DJ16 -> 0 | DK16: =+PMGR!DK16+BP!DK16 -> 0 | DL16: =+PMGR!DL16+BP!DL16 -> 0 | DM16: =+PMGR!DM16+BP!DM16 -> 0 | DN16: =+PMGR!DN16+BP!DN16 -> 0 | DO16: =+PMGR!DO16+BP!DO16 -> 0 | DP16: =+PMGR!DP16+BP!DP16 -> 0 | ... DT16: =+PMGR!DT16+BP!DT16 -> 0 | DU16: =+SUM(DI16:DT16) -> 0 | DW16: =+PMGR!DW16+BP!DW16 -> 0 | DX16: =+PMGR!DX16+BP!DX16 -> 0 | DY16: =+PMGR!DY16+BP!DY16 -> 0 | DZ16: =+PMGR!DZ16+BP!DZ16 -> 0 | EA16: =+PMGR!EA16+BP!EA16 -> 0 | EB16: =+PMGR!EB16+BP!EB16 -> 0 | EC16: =+PMGR!EC16+BP!EC16 -> 0 | ED16: =+PMGR!ED16+BP!ED16 -> 0 | ... EH16: =+PMGR!EH16+BP!EH16 -> 0 | EI16: =+SUM(DW16:EH16) -> 0 | EJ16: =CT16 -> Marketing And Process Steering | EK16: =+PMGR!EK16+BP!EK16 -> 0 | EL16: =+PMGR!EL16+BP!EL16 -> 0 | EM16: =+PMGR!EM16+BP!EM16 -> 0 | EN16: =+PMGR!EN16+BP!EN16 -> 0 | EO16: =+PMGR!EO16+BP!EO16 -> 0 | EP16: =+PMGR!EP16+BP!EP16 -> 0 | EQ16: =+PMGR!EQ16+BP!EQ16 -> 0 | ER16: =+PMGR!ER16+BP!ER16 -> 0 | ... EV16: =+PMGR!EV16+BP!EV16 -> 0 | EW16: =+SUM(EK16:EV16) -> 0 | EY16: =+PMGR!EY16+BP!EY16 -> 0 | EZ16: =+PMGR!EZ16+BP!EZ16 -> 0 | FA16: =+PMGR!FA16+BP!FA16 -> 0 | FB16: =+PMGR!FB16+BP!FB16 -> 0 | FC16: =+PMGR!FC16+BP!FC16 -> 0 | FD16: =+PMGR!FD16+BP!FD16 -> 0 | FE16: =+PMGR!FE16+BP!FE16 -> 0 | FF16: =+PMGR!FF16+BP!FF16 -> 0 | ... FJ16: =+PMGR!FJ16+BP!FJ16 -> 0 | FK16: =+SUM(EY16:FJ16) -> 0
N17: Sales Demo Car | BD17: =N17 -> Sales Demo Car | CT17: =BD17 -> Sales Demo Car | EJ17: =CT17 -> Sales Demo Car
A18: =+AQ18+CG18+DW18 -> 0 | B18: =+AR18+CH18+DX18 -> 0 | C18: =+AS18+CI18+DY18 -> 0 | D18: =+AT18+CJ18+DZ18 -> 0 | E18: =+AU18+CK18+EA18 -> 0 | F18: =+AV18+CL18+EB18 -> 0 | G18: =+AW18+CM18+EC18 -> 0 | H18: =+AX18+CN18+ED18 -> 0 | ... L18: =+BB18+CR18+EH18 -> 0 | M18: =+SUM(A18:L18) -> 0 | N18: No of Cars Sold | O18: =+BE18+CU18+EK18 -> 0 | P18: =+BF18+CV18+EL18 -> 0 | Q18: =+BG18+CW18+EM18 -> 0 | R18: =+BH18+CX18+EN18 -> 0 | S18: =+BI18+CY18+EO18 -> 0 | T18: =+BJ18+CZ18+EP18 -> 0 | U18: =+BK18+DA18+EQ18 -> 0 | V18: =+BL18+DB18+ER18 -> 0 | ... Z18: =+BP18+DF18+EV18 -> 0 | AA18: =+SUM(O18:Z18) -> 0 | AC18: =+BS18+DI18+EY18 -> 0 | AD18: =+BT18+DJ18+EZ18 -> 0 | AE18: =+BU18+DK18+FA18 -> 0 | AF18: =+BV18+DL18+FB18 -> 0 | AG18: =+BW18+DM18+FC18 -> 0 | AH18: =+BX18+DN18+FD18 -> 0 | AI18: =+BY18+DO18+FE18 -> 0 | AJ18: =+BZ18+DP18+FF18 -> 0 | ... AN18: =+CD18+DT18+FJ18 -> 0 | AO18: =+SUM(AC18:AN18) -> 0 | AQ18: =+PMGR!AQ18+BP!AQ18 -> 0 | AR18: =+PMGR!AR18+BP!AR18 -> 0 | AS18: =+PMGR!AS18+BP!AS18 -> 0 | AT18: =+PMGR!AT18+BP!AT18 -> 0 | AU18: =+PMGR!AU18+BP!AU18 -> 0 | AV18: =+PMGR!AV18+BP!AV18 -> 0 | AW18: =+PMGR!AW18+BP!AW18 -> 0 | AX18: =+PMGR!AX18+BP!AX18 -> 0 | ... BB18: =+PMGR!BB18+BP!BB18 -> 0 | BC18: =+SUM(AQ18:BB18) -> 0 | BD18: =N18 -> No of Cars Sold | BE18: =+PMGR!BE18+BP!BE18 -> 0 | BF18: =+PMGR!BF18+BP!BF18 -> 0 | BG18: =+PMGR!BG18+BP!BG18 -> 0 | BH18: =+PMGR!BH18+BP!BH18 -> 0 | BI18: =+PMGR!BI18+BP!BI18 -> 0 | BJ18: =+PMGR!BJ18+BP!BJ18 -> 0 | BK18: =+PMGR!BK18+BP!BK18 -> 0 | BL18: =+PMGR!BL18+BP!BL18 -> 0 | ... BP18: =+PMGR!BP18+BP!BP18 -> 0 | BQ18: =+SUM(BE18:BP18) -> 0 | BS18: =+PMGR!BS18+BP!BS18 -> 0 | BT18: =+PMGR!BT18+BP!BT18 -> 0 | BU18: =+PMGR!BU18+BP!BU18 -> 0 | BV18: =+PMGR!BV18+BP!BV18 -> 0 | BW18: =+PMGR!BW18+BP!BW18 -> 0 | BX18: =+PMGR!BX18+BP!BX18 -> 0 | BY18: =+PMGR!BY18+BP!BY18 -> 0 | BZ18: =+PMGR!BZ18+BP!BZ18 -> 0 | ... CD18: =+PMGR!CD18+BP!CD18 -> 0 | CE18: =+SUM(BS18:CD18) -> 0 | CG18: =+PMGR!CG18+BP!CG18 -> 0 | CH18: =+PMGR!CH18+BP!CH18 -> 0 | CI18: =+PMGR!CI18+BP!CI18 -> 0 | CJ18: =+PMGR!CJ18+BP!CJ18 -> 0 | CK18: =+PMGR!CK18+BP!CK18 -> 0 | CL18: =+PMGR!CL18+BP!CL18 -> 0 | CM18: =+PMGR!CM18+BP!CM18 -> 0 | CN18: =+PMGR!CN18+BP!CN18 -> 0 | ... CR18: =+PMGR!CR18+BP!CR18 -> 0 | CS18: =+SUM(CG18:CR18) -> 0 | CT18: =BD18 -> No of Cars Sold | CU18: =+PMGR!CU18+BP!CU18 -> 0 | CV18: =+PMGR!CV18+BP!CV18 -> 0 | CW18: =+PMGR!CW18+BP!CW18 -> 0 | CX18: =+PMGR!CX18+BP!CX18 -> 0 | CY18: =+PMGR!CY18+BP!CY18 -> 0 | CZ18: =+PMGR!CZ18+BP!CZ18 -> 0 | DA18: =+PMGR!DA18+BP!DA18 -> 0 | DB18: =+PMGR!DB18+BP!DB18 -> 0 | ... DF18: =+PMGR!DF18+BP!DF18 -> 0 | DG18: =+SUM(CU18:DF18) -> 0 | DI18: =+PMGR!DI18+BP!DI18 -> 0 | DJ18: =+PMGR!DJ18+BP!DJ18 -> 0 | DK18: =+PMGR!DK18+BP!DK18 -> 0 | DL18: =+PMGR!DL18+BP!DL18 -> 0 | DM18: =+PMGR!DM18+BP!DM18 -> 0 | DN18: =+PMGR!DN18+BP!DN18 -> 0 | DO18: =+PMGR!DO18+BP!DO18 -> 0 | DP18: =+PMGR!DP18+BP!DP18 -> 0 | ... DT18: =+PMGR!DT18+BP!DT18 -> 0 | DU18: =+SUM(DI18:DT18) -> 0 | DW18: =+PMGR!DW18+BP!DW18 -> 0 | DX18: =+PMGR!DX18+BP!DX18 -> 0 | DY18: =+PMGR!DY18+BP!DY18 -> 0 | DZ18: =+PMGR!DZ18+BP!DZ18 -> 0 | EA18: =+PMGR!EA18+BP!EA18 -> 0 | EB18: =+PMGR!EB18+BP!EB18 -> 0 | EC18: =+PMGR!EC18+BP!EC18 -> 0 | ED18: =+PMGR!ED18+BP!ED18 -> 0 | ... EH18: =+PMGR!EH18+BP!EH18 -> 0 | EI18: =+SUM(DW18:EH18) -> 0 | EJ18: =CT18 -> No of Cars Sold | EK18: =+PMGR!EK18+BP!EK18 -> 0 | EL18: =+PMGR!EL18+BP!EL18 -> 0 | EM18: =+PMGR!EM18+BP!EM18 -> 0 | EN18: =+PMGR!EN18+BP!EN18 -> 0 | EO18: =+PMGR!EO18+BP!EO18 -> 0 | EP18: =+PMGR!EP18+BP!EP18 -> 0 | EQ18: =+PMGR!EQ18+BP!EQ18 -> 0 | ER18: =+PMGR!ER18+BP!ER18 -> 0 | ... EV18: =+PMGR!EV18+BP!EV18 -> 0 | EW18: =+SUM(EK18:EV18) -> 0 | EY18: =+PMGR!EY18+BP!EY18 -> 0 | EZ18: =+PMGR!EZ18+BP!EZ18 -> 0 | FA18: =+PMGR!FA18+BP!FA18 -> 0 | FB18: =+PMGR!FB18+BP!FB18 -> 0 | FC18: =+PMGR!FC18+BP!FC18 -> 0 | FD18: =+PMGR!FD18+BP!FD18 -> 0 | FE18: =+PMGR!FE18+BP!FE18 -> 0 | FF18: =+PMGR!FF18+BP!FF18 -> 0 | ... FJ18: =+PMGR!FJ18+BP!FJ18 -> 0 | FK18: =+SUM(EY18:FJ18) -> 0
